Workbook

Sheet 1
A1: 제1항 총 설
A3: 1. 서언
A4: 이 절에서는 법원에서 관장하고 있는 사건(법원조직법 제2조)을 통계분석의 편의상 소송사건과 비송사건으로 분류하고, 다시 소송사건은 민사·가사·행정·지식재산·선거·형사·소년보호·가정보호·인신보호사건 등으로, 비송사건은 등기·가족관계등록·공탁사건으로 분류하여, 전체사건의 동향을 정리·분석한다. 그리고 사건의 분석방법으로써 제1항에서는 전체사건의 개황, 인구와 사건과의 대비를 살펴보고, 제2항 이하에서는 각종 사건의 중요한 사항을 종류별로 요약·검토하며 다만, 사건의 증감추세는 "제2절 사건의 추이(누년비교)"로, 사건의 구체적 현황은 "제3절 사건의 현황(세별표)"으로 각 별개의 절에서 다룬다.
A7: 2. 전체사건의 개황
A8: 2022년도에 전국 법원에 접수된 사건은 총 16,023,852건으로 이를 법원별·심급별·사건별로 정리하면 표 1과 같다. 사건의 종류별 구성을 보면 도표 1과 같이 소송사건은 6,167,312건이고, 비송사건은 9,856,540건으로 그 비율은 38대 62이다. 소송사건을 본안사건(민사·가사·행정·지식재산·선거·형사공판·치료감호사건)과 본안외사건(민사조정·독촉·집행·신청·비송·기타사건, 가사비송·조정·신청·기타사건, 행정신청, 지식재산신청, 기타사건, 형사약식·성매매관련보호·즉결·영장·신청·기타사건, 소년보호·가정보호·인신보호사건, 피해자보호명령, 아동보호명령, 피해아동보호명령, 감치·과태료사건)으로 구분하면 도표 2와 같이 본안사건은 1,221,301건으로 전체 소송사건의 19.8%를, 본안외사건은 4,946,011건으로 전체 소송사건의 80.2%를 각 차지하고 있다.
A11: 비송사건 | B11: 9856540 | C11: 61.511676
A12: 소송사건 | B12: 6167312 | C12: 38.488324 | G12: 본안외사건 | H12: 4946011 | I12: 80.197191
B13: 16023852 | G13: 본안사건 | H13: 1221301 | I13: 19.802809

Sheet 2
A1: 다음으로 소송사건을 사건별로 살펴보면 도표 3과 같다. 민사사건이 소송사건의 68.6%, 형사사건이 소송사건의 25.6%를 각 차지하고 있다. 전체사건의 61.5%를 차지하고 있는 비송사건의 구성비를 보면 도표 4와 같고, 등기사건이 전체 비송사건의 95.7%를 차지하고 있다. 또한 전체사건, 본안사건, 본안외사건 및 비송사건등에 대한 심급 및 법원별 접수 상황은 표 1과 같고 이들 사건에 대한 2013년 이후에 동향은 표 2와 같다. 이를 기초로 사건의 추이를 보면 도표 5와 같다
G4: 등기 | H4: 가족관계등록비송 | I4: 공탁
G5: 9433210 | H5: 235263 | I5: 188067
A11: 민사 | B11: 형사 | C11: 가사 | D11: 소년 | E11: 행정 | F11: 지식재산 | G11: 선거
A12: 4227700 | B12: 1579320 | C12: 177310 | D12: 131923 | E12: 49900 | F12: 1036 | G12: 123
A17: 주 : 형사사건에는 감치·과태료사건(60,439건), 인신보호사건(1,165건), 성매매관련(169건)이 포함됨
D21: 전체사건 대 각 사건별 대비(도표5)
E22: 전체사건 | F22: 본안사건 | G22: 본안외사건 | H22: 비송사건
D23: 10 | E23: 17405933 | F23: 1482074 | G23: 4734122 | H23: 11189737
D24: 11 | E24: 18295844 | F24: 1503696 | G24: 4784127 | H24: 12008021
D25: 12 | E25: 18020244 | F25: 1573655 | G25: 4744390 | H25: 11702199
D26: 13 | E26: 18466987 | F26: 1605623 | G26: 4985097 | H26: 11876267
D27: 14 | E27: 18986585 | F27: 1657385 | G27: 4843459 | H27: 12485741
D28: 15 | E28: 20609851 | F28: 1525846 | G28: 4835939 | H28: 14248066
D29: 16 | E29: 18978570 | F29: 1523108 | G29: 5224405 | H29: 12231057
D30: 17 | E30: 18069526 | F30: 1555602 | G30: 5187181 | H30: 11326743
D31: 18 | E31: 17651498 | F31: 1462714 | G31: 5122866 | H31: 11065918
D32: 19 | E32: 17720328 | F32: 1461440 | G32: 5172904 | H32: 11085984
D33: 20 | E33: 18838150 | F33: 1448551 | G33: 5230682 | H33: 12158917
D34: 21 | E34: 17884639 | F34: 1297441 | G34: 4994026 | H34: 11593172
D35: 22 | E35: 16023852 | F35: 1221301 | G35: 4946011 | H35: 9856540

Sheet 3
A1: 가. 총괄
A2: 구분 | B2: 총계 | C2: 소 송 사 건 | K2: 비 송 사 건
A3: 법원 | C3: 합계 | D3: 민사 | E3: 가사 | F3: 행정 | G3: 지식재산 | H3: 선거 | I3: 형사 | J3: 소년 | K3: 합계 | L3: 등기 | M3: 가족관계등록비송 | N3: 공탁
A4: 총계 | B4: 16023852 | C4: 6167312 | D4: 4227700 | E4: 177310 | F4: 49900 | G4: 1036 | H4: 123 | I4: 1579320 | J4: 131923 | K4: 9856540 | L4: 9433210 | M4: 235263 | N4: 188067
A5: 대법원 | B5: 72352 | C5: 72352 | D5: 38350 | E5: 1161 | F5: 6727 | G5: 164 | H5: 97 | I5: 25634 | J5: 219 | K5: 0 | L5: 0 | M5: 0 | N5: 0
A6: 고등법원합계 | B6: 60264 | C6: 60264 | D6: 19640 | E6: 2435 | F6: 9490 | G6: 872 | H6: 9 | I6: 27818 | J6: 0 | K6: 0 | L6: 0 | M6: 0 | N6: 0
A7: 지방법원합계 | B7: 15891236 | C7: 6034696 | D7: 4169710 | E7: 173714 | F7: 33683 | G7: 0 | H7: 17 | I7: 1525868 | J7: 131704 | K7: 9856540 | L7: 9433210 | M7: 235263 | N7: 188067
A8: 항소심계 | B8: 128622 | C8: 128622 | D8: 58480 | E8: 4147 | F8: 0 | G8: 0 | H8: 0 | I8: 63770 | J8: 2225 | K8: 0 | L8: 0 | M8: 0 | N8: 0
A9: 제1심계 | B9: 15762614 | C9: 5906074 | D9: 4111230 | E9: 169567 | F9: 33683 | G9: 0 | H9: 17 | I9: 1462098 | J9: 129479 | K9: 9856540 | L9: 9433210 | M9: 235263 | N9: 188067
A10: 주 : 감치·과태료 60,439건(상고심 8건, 항소심 43건, 제1심 60,388건)과 인신보호 1,165건(상고심 14건, 지법항소심 64건, 제1심 1,087건), 성매매관련 169건(지법항소심 2건, 제1심 167건)은 형사란에, 가정보호 47,101건(상고심 97건, 지법항소심 1,091건, 제1심 45,913건), 피해자보호명령 2,912건(상고심 19건, 지법항소심 233건, 제1심 2,660건), 아동보호명령 20,320건(상고심 59건, 지법항소심 580건, 제1심 19,681건), 피해아동보호명령 1,381건(상고심 24건, 지법항소심 102건, 제1심 1,255건)은 소년란에 각각 합산하였음
A12: 나. 대법원
A13: 구분 | B13: 합 계 | D13: 민 사 | F13: 가 사 | H13: 행 정 | J13: 지식재산 | L13: 선 거 | N13: 형 사 | Q13: 소년 | R13: 가정보호 | S13: 피해자보호명령 | T13: 아동보호 | U13: 피해아동보호명령 | V13: 인신보호 | W13: 성매매관련보호
A14: 법원 | B14: 본안 | C14: 본안외 | D14: 본안 | E14: 본안외 | F14: 본안 | G14: 본안외 | H14: 본안 | I14: 본안외 | J14: 본안 | K14: 본안외 | L14: 본안 | M14: 본안외 | N14: 공판 | O14: 치료감호 | P14: 본안외
A15: 대법원 | B15: 52480 | C15: 19872 | D15: 28284 | E15: 10066 | F15: 705 | G15: 456 | H15: 4126 | I15: 2601 | J15: 126 | K15: 38 | L15: 41 | M15: 56 | N15: 19179 | O15: 19 | P15: 6422 | Q15: 20 | R15: 97 | S15: 19 | T15: 59 | U15: 24 | V15: 14 | W15: 0
A17: 다. 고등법원
A18: 구분 | B18: 합 계 | D18: 민 사 | F18: 가 사 | H18: 행 정 | J18: 지식재산 | L18: 선 거 | N18: 형 사
A19: 법원 | B19: 본안 | C19: 본안외 | D19: 본안 | E19: 본안외 | F19: 본안 | G19: 본안외 | H19: 본안 | I19: 본안외 | J19: 본안 | K19: 본안외 | L19: 본안 | M19: 본안외 | N19: 공판 | O19: 치료감호 | P19: 본안외
A20: 합계 | B20: 32037 | C20: 28227 | D20: 12529 | E20: 7111 | F20: 1575 | G20: 860 | H20: 7226 | I20: 2264 | J20: 562 | K20: 310 | L20: 5 | M20: 4 | N20: 10059 | O20: 81 | P20: 17678
A21: 서울고등법원 | B21: 16043 | C21: 13527 | D21: 6367 | E21: 3784 | F21: 664 | G21: 457 | H21: 4528 | I21: 1291 | J21: 0 | K21: 0 | L21: 3 | M21: 1 | N21: 4449 | O21: 32 | P21: 7994
A22: 대전고등법원 | B22: 2494 | C22: 2297 | D22: 914 | E22: 531 | F22: 136 | G22: 71 | H22: 494 | I22: 260 | J22: 0 | K22: 0 | L22: 0 | M22: 0 | N22: 936 | O22: 14 | P22: 1435
A23: 대구고등법원 | B23: 1882 | C23: 2543 | D23: 761 | E23: 424 | F23: 62 | G23: 41 | H23: 341 | I23: 100 | J23: 0 | K23: 0 | L23: 0 | M23: 0 | N23: 710 | O23: 8 | P23: 1978
A24: 부산고등법원 | B24: 3806 | C24: 3791 | D24: 1531 | E24: 714 | F24: 210 | G24: 76 | H24: 659 | I24: 265 | J24: 0 | K24: 0 | L24: 2 | M24: 3 | N24: 1395 | O24: 9 | P24: 2733
A25: 광주고등법원 | B25: 2781 | C25: 2294 | D25: 986 | E25: 538 | F25: 122 | G25: 48 | H25: 594 | I25: 168 | J25: 0 | K25: 0 | L25: 0 | M25: 0 | N25: 1067 | O25: 12 | P25: 1540
A26: 수원고등법원 | B26: 4327 | C26: 3392 | D26: 1828 | E26: 1047 | F26: 381 | G26: 167 | H26: 610 | I26: 180 | J26: 0 | K26: 0 | L26: 0 | M26: 0 | N26: 1502 | O26: 6 | P26: 1998
A27: 특허법원 | B27: 704 | C27: 383 | D27: 142 | E27: 73 | F27: 0 | G27: 0 | H27: 0 | I27: 0 | J27: 562 | K27: 310 | L27: 0 | M27: 0 | N27: 0 | O27: 0 | P27: 0
A29: 라. 지방법원(항소심)
A30: 구분 | B30: 합계 | D30: 민사 | F30: 가사 | H30: 형사 | J30: 소년 | K30: 가정 보호 | L30: 피해자 보호 명령 | M30: 아동 보호 | N30: 피해아동 보호명령 | O30: 인신 보호 | P30: 성매매 관련 보호
A31: 법원 | B31: 본안 | C31: 본안외 | D31: 본안 | E31: 본안외 | F31: 본안 | G31: 본안외 | H31: 본안 | I31: 본안외
A32: 합계 | B32: 108733 | C32: 19889 | D32: 44961 | E32: 13519 | F32: 2664 | G32: 1483 | H32: 61108 | I32: 2596 | J32: 219 | K32: 1091 | L32: 233 | M32: 580 | N32: 102 | O32: 64 | P32: 2
A33: 서울중앙지방법원 | B33: 12218 | C33: 1142 | D33: 8162 | E33: 942 | F33: 0 | G33: 0 | H33: 4056 | I33: 200 | J33: 0 | K33: 0 | L33: 0 | M33: 0 | N33: 0 | O33: 0 | P33: 0
A34: 서울가정법원 | B34: 407 | C34: 738 | D34: 0 | E34: 0 | F34: 407 | G34: 213 | H34: 0 | I34: 9 | J34: 40 | K34: 287 | L34: 65 | M34: 104 | N34: 20 | O34: 0 | P34: 0
A35: 서울회생법원 | B35: 0 | C35: 514 | D35: 0 | E35: 514 | F35: 0 | G35: 0 | H35: 0 | I35: 0 | J35: 0 | K35: 0 | L35: 0 | M35: 0 | N35: 0 | O35: 0 | P35: 0
A36: 서울동부지방법원 | B36: 3693 | C36: 388 | D36: 1787 | E36: 311 | F36: 0 | G36: 1 | H36: 1906 | I36: 74 | J36: 0 | K36: 0 | L36: 0 | M36: 0 | N36: 0 | O36: 2 | P36: 0
A37: 서울남부지방법원 | B37: 4349 | C37: 487 | D37: 1997 | E37: 362 | F37: 0 | G37: 5 | H37: 2352 | I37: 118 | J37: 0 | K37: 0 | L37: 0 | M37: 0 | N37: 0 | O37: 2 | P37: 0
A38: 서울북부지방법원 | B38: 3779 | C38: 414 | D38: 1461 | E38: 277 | F38: 0 | G38: 8 | H38: 2318 | I38: 126 | J38: 0 | K38: 0 | L38: 0 | M38: 0 | N38: 0 | O38: 3 | P38: 0
A39: 서울서부지방법원 | B39: 2675 | C39: 342 | D39: 1148 | E39: 252 | F39: 0 | G39: 7 | H39: 1527 | I39: 82 | J39: 0 | K39: 0 | L39: 0 | M39: 0 | N39: 0 | O39: 1 | P39: 0
A40: 의정부지방법원 | B40: 6836 | C40: 1231 | D40: 2439 | E40: 866 | F40: 121 | G40: 95 | H40: 4276 | I40: 132 | J40: 21 | K40: 63 | L40: 22 | M40: 23 | N40: 7 | O40: 2 | P40: 0
A41: 인천지방법원 | B41: 8914 | C41: 1729 | D41: 3192 | E41: 1135 | F41: 277 | G41: 110 | H41: 5445 | I41: 272 | J41: 12 | K41: 92 | L41: 21 | M41: 74 | N41: 9 | O41: 4 | P41: 0
A42: 수원지방법원 | B42: 14908 | C42: 3114 | D42: 5890 | E42: 2059 | F42: 442 | G42: 265 | H42: 8576 | I42: 349 | J42: 19 | K42: 219 | L42: 40 | M42: 138 | N42: 16 | O42: 9 | P42: 0
A43: 춘천지방법원 | B43: 3248 | C43: 581 | D43: 957 | E43: 433 | F43: 93 | G43: 55 | H43: 2198 | I43: 50 | J43: 7 | K43: 21 | L43: 6 | M43: 8 | N43: 1 | O43: 0 | P43: 0
...

Sheet 4
A1: 지방법원(제1심)
A2: 구분 | B2: 총계 | C2: 소 송 사 건 | AI2: 비 송 사 건
C3: 합 계 | E3: 민 사 | N3: 가 사 | R3: 행정·선거 | T3: 형 사 | AA3: 소년 | AB3: 가정보호 | AC3: 피해자 보호 명령 | AD3: 아동 보호 | AE3: 피해아동보호명령 | AF3: 인신 보호 | AG3: 성매매 관련 보호 | AH3: 감치 과태료 | AI3: 합 계 | AJ3: 등 기 | AK3: 가족 관계 등록 | AL3: 공 탁
C4: 본안 | D4: 기타 (비송제외) | E4: 본 안 | H4: 본 안 외 | N4: 본안 | O4: 본안외 | R4: 본안 | S4: 본안외 | T4: 본 안 | W4: 본 안 외
A5: 법원 | E5: 합의 | F5: 단독 | G5: 소액 | H5: 조정 | I5: 독촉 | J5: 집행 | K5: 비송 | L5: 신청 | M5: 도산 | O5: 조정 | P5: 비송 | Q5: 신청 | T5: 합의 | U5: 단독 | V5: 치료감호 | W5: 즉결 | X5: 약식 | Y5: 영장 | Z5: 신청
A6: 합 계 | B6: 15762614 | C6: 1028051 | D6: 4878023 | E6: 27726 | F6: 223821 | G6: 492576 | H6: 65630 | I6: 1040923 | J6: 1225850 | K6: 80432 | L6: 775154 | M6: 179118 | N6: 41966 | O6: 8024 | P6: 92937 | Q6: 26640 | R6: 21906 | S6: 11794 | T6: 21287 | U6: 198621 | V6: 148 | W6: 135327 | X6: 416410 | Y6: 526426 | Z6: 102237 | AA6: 59970 | AB6: 45913 | AC6: 2660 | AD6: 19681 | AE6: 1255 | AF6: 1087 | AG6: 167 | AH6: 60388 | AI6: 9856540 | AJ6: 9433210 | AK6: 235263 | AL6: 188067
A7: 서울중앙지방법원 | B7: 1295614 | C7: 219288 | D7: 535803 | E7: 7189 | F7: 42893 | G7: 156659 | H7: 12970 | I7: 309716 | J7: 46962 | K7: 6919 | L7: 81083 | M7: 0 | N7: 0 | O7: 0 | P7: 0 | Q7: 0 | R7: 0 | S7: 2 | T7: 1420 | U7: 11118 | V7: 9 | W7: 5532 | X7: 22837 | Y7: 40046 | Z7: 8147 | AA7: 0 | AB7: 0 | AC7: 0 | AD7: 0 | AE7: 0 | AF7: 16 | AG7: 0 | AH7: 1573 | AI7: 540523 | AJ7: 517072 | AK7: 0 | AL7: 23451
A8: 서울가정법원 | B8: 58923 | C8: 8081 | D8: 41931 | E8: 0 | F8: 0 | G8: 0 | H8: 0 | I8: 0 | J8: 0 | K8: 0 | L8: 0 | M8: 0 | N8: 8081 | O8: 2765 | P8: 17301 | Q8: 4563 | R8: 0 | S8: 0 | T8: 0 | U8: 0 | V8: 0 | W8: 0 | X8: 0 | Y8: 0 | Z8: 0 | AA8: 7776 | AB8: 6568 | AC8: 418 | AD8: 2182 | AE8: 150 | AF8: 0 | AG8: 18 | AH8: 190 | AI8: 8911 | AJ8: 0 | AK8: 8911 | AL8: 0
A9: 서울행정법원 | B9: 13263 | C9: 8493 | D9: 4770 | E9: 0 | F9: 0 | G9: 0 | H9: 0 | I9: 0 | J9: 0 | K9: 0 | L9: 0 | M9: 0 | N9: 0 | O9: 0 | P9: 0 | Q9: 0 | R9: 8493 | S9: 4770 | T9: 0 | U9: 0 | V9: 0 | W9: 0 | X9: 0 | Y9: 0 | Z9: 0 | AA9: 0 | AB9: 0 | AC9: 0 | AD9: 0 | AE9: 0 | AF9: 0 | AG9: 0 | AH9: 0 | AI9: 0 | AJ9: 0 | AK9: 0 | AL9: 0
A10: 서울회생법원 | B10: 39526 | C10: 209 | D10: 39317 | E10: 209 | F10: 0 | G10: 0 | H10: 0 | I10: 0 | J10: 0 | K10: 0 | L10: 119 | M10: 39198 | N10: 0 | O10: 0 | P10: 0 | Q10: 0 | R10: 0 | S10: 0 | T10: 0 | U10: 0 | V10: 0 | W10: 0 | X10: 0 | Y10: 0 | Z10: 0 | AA10: 0 | AB10: 0 | AC10: 0 | AD10: 0 | AE10: 0 | AF10: 0 | AG10: 0 | AH10: 0 | AI10: 0 | AJ10: 0 | AK10: 0 | AL10: 0
A11: 서울동부지방법원 | B11: 364910 | C11: 42063 | D11: 141495 | E11: 1069 | F11: 7547 | G11: 28123 | H11: 3773 | I11: 41479 | J11: 31537 | K11: 3629 | L11: 21947 | M11: 0 | N11: 0 | O11: 0 | P11: 0 | Q11: 0 | R11: 0 | S11: 1 | T11: 499 | U11: 4823 | V11: 2 | W11: 4927 | X11: 10827 | Y11: 18827 | Z11: 2697 | AA11: 0 | AB11: 364 | AC11: 0 | AD11: 161 | AE11: 0 | AF11: 14 | AG11: 0 | AH11: 1312 | AI11: 181352 | AJ11: 171664 | AK11: 6263 | AL11: 3425
A12: 서울남부지방법원 | B12: 550984 | C12: 64991 | D12: 204513 | E12: 1261 | F12: 11578 | G12: 44134 | H12: 5755 | I12: 73898 | J12: 39797 | K12: 3644 | L12: 29068 | M12: 0 | N12: 0 | O12: 0 | P12: 0 | Q12: 0 | R12: 0 | S12: 0 | T12: 697 | U12: 7316 | V12: 5 | W12: 8193 | X12: 13880 | Y12: 22731 | Z12: 4714 | AA12: 0 | AB12: 679 | AC12: 0 | AD12: 346 | AE12: 0 | AF12: 43 | AG12: 0 | AH12: 1765 | AI12: 281480 | AJ12: 269085 | AK12: 8230 | AL12: 4165
A13: 서울북부지방법원 | B13: 391525 | C13: 30368 | D13: 147796 | E13: 622 | F13: 6572 | G13: 15145 | H13: 2485 | I13: 24783 | J13: 43519 | K13: 2653 | L13: 23172 | M13: 0 | N13: 0 | O13: 0 | P13: 0 | Q13: 0 | R13: 0 | S13: 1 | T13: 641 | U13: 7384 | V13: 4 | W13: 10460 | X13: 14049 | Y13: 20607 | Z13: 3405 | AA13: 0 | AB13: 451 | AC13: 0 | AD13: 203 | AE13: 0 | AF13: 57 | AG13: 0 | AH13: 1951 | AI13: 213361 | AJ13: 197288 | AK13: 8606 | AL13: 7467
A14: 서울서부지방법원 | B14: 339126 | C14: 29736 | D14: 134830 | E14: 864 | F14: 10762 | G14: 13367 | H14: 2826 | I14: 52393 | J14: 23686 | K14: 2898 | L14: 17484 | M14: 0 | N14: 0 | O14: 0 | P14: 0 | Q14: 0 | R14: 0 | S14: 1 | T14: 478 | U14: 4265 | V14: 0 | W14: 4130 | X14: 9118 | Y14: 18030 | Z14: 2425 | AA14: 0 | AB14: 384 | AC14: 0 | AD14: 188 | AE14: 0 | AF14: 7 | AG14: 0 | AH14: 1260 | AI14: 174560 | AJ14: 165642 | AK14: 5348 | AL14: 3570
A15: 의정부지방법원 | B15: 375172 | C15: 18498 | D15: 126116 | E15: 609 | F15: 4247 | G15: 5845 | H15: 1484 | I15: 12853 | J15: 33425 | K15: 2155 | L15: 20214 | M15: 11618 | N15: 1095 | O15: 163 | P15: 2880 | Q15: 805 | R15: 1053 | S15: 599 | T15: 551 | U15: 5094 | V15: 4 | W15: 4632 | X15: 10235 | Y15: 13800 | Z15: 2994 | AA15: 4486 | AB15: 739 | AC15: 82 | AD15: 659 | AE15: 38 | AF15: 64 | AG15: 5 | AH15: 2186 | AI15: 230558 | AJ15: 217551 | AK15: 5622 | AL15: 7385
A16: 고양지원 | B16: 420586 | C16: 19442 | D16: 109014 | E16: 564 | F16: 5307 | G16: 7256 | H16: 1215 | I16: 14491 | J16: 34456 | K16: 2640 | L16: 20263 | M16: 0 | N16: 1162 | O16: 203 | P16: 2883 | Q16: 894 | R16: 0 | S16: 0 | T16: 424 | U16: 4728 | V16: 1 | W16: 2670 | X16: 10671 | Y16: 13745 | Z16: 1997 | AA16: 0 | AB16: 1229 | AC16: 79 | AD16: 493 | AE16: 16 | AF16: 36 | AG16: 3 | AH16: 1030 | AI16: 292130 | AJ16: 281800 | AK16: 6791 | AL16: 3539
A17: 남양주지원 | B17: 269328 | C17: 10189 | D17: 57517 | E17: 201 | F17: 2596 | G17: 4603 | H17: 203 | I17: 9987 | J17: 17186 | K17: 1456 | L17: 9432 | M17: 0 | N17: 616 | O17: 153 | P17: 1359 | Q17: 367 | R17: 0 | S17: 2 | T17: 180 | U17: 1993 | V17: 0 | W17: 3679 | X17: 6003 | Y17: 5747 | Z17: 555 | AA17: 0 | AB17: 501 | AC17: 36 | AD17: 271 | AE17: 7 | AF17: 0 | AG17: 0 | AH17: 573 | AI17: 201622 | AJ17: 195986 | AK17: 3958 | AL17: 1678
... A88: 제주지방법원 | B88: 263759 | C88: 12991 | D88: 72559 | E88: 302 | F88: 2910 | G88: 4304 | H88: 139 | I88: 9503 | J88: 20073 | K88: 1584 | L88: 11726 | M88: 2459 | N88: 669 | O88: 58 | P88: 1422 | Q88: 417 | R88: 180 | S88: 120 | T88: 1059 | U88: 3561 | V88: 6 | W88: 1953 | X88: 8409 | Y88: 9425 | Z88: 1975 | AA88: 771 | AB88: 1163 | AC88: 42 | AD88: 374 | AE88: 25 | AF88: 4 | AG88: 1 | AH88: 916 | AI88: 178209 | AJ88: 172420 | AK88: 3726 | AL88: 2063
A89: 주: 시·군법원 및 등기소의 각 사건은 소속법원(본원 또는 지원)에 합산하였음
A91: 구분 | B91: 총계 | C91: 합계 | E91: 민 사 | N91: 가 사 | R91: 행정.선거 | T91: 형사 | AA91: 소년 | AB91: 가정보호 | AC91: 피해자 보호명령 | AD91: 아동 보호 | AE91: 피해아동보호명령 | AF91: 인신 보호 | AG91: 성매매 관련보호 | AH91: 감치 과태료 | AI91: 합계 | AJ91: 등기 | AK91: 가족관계등록비송 | AL91: 공탁
A92: 법원 | C92: 본안 | D92: 기타 (비송제외) | E92: 합의 | F92: 단독 | G92: 소액 | H92: 조정 | I92: 독촉 | J92: 집행 | K92: 비송 | L92: 신청 | M92: 도산 | N92: 본안 | O92: 조정 | P92: 비송 | Q92: 신청 | R92: 본안 | S92: 본안외 | T92: 합의 | U92: 단독 | V92: 치료감호 | W92: 즉결 | X92: 약식 | Y92: 영장 | Z92: 신청
A93: 계 | B93: 15762614 | C93: 1028051 | D93: 4878023 | AI93: 9856540
A94: 서울중앙 | B94: 1407326 | C94: 236071 | D94: 621821 | AI94: 549434
A95: 서울동부 | B95: 364910 | C95: 42063 | D95: 141495 | AI95: 181352
A96: 서울남부 | B96: 550984 | C96: 64991 | D96: 204513 | AI96: 281480
A97: 서울북부 | B97: 391525 | C97: 30368 | D97: 147796 | AI97: 213361
A98: 서울서부 | B98: 339126 | C98: 29736 | D98: 134830 | AI98: 174560
A99: 의정부 | B99: 1065086 | C99: 48129 | D99: 292647 | AI99: 724310
A100: 인천 | B100: 1279533 | C100: 70191 | D100: 404099 | AI100: 805243
A101: 수원 | B101: 2491569 | C101: 124054 | D101: 679117 | AI101: 1688398
A102: 춘천 | B102: 537293 | C102: 20486 | D102: 123318 | AI102: 393489
A103: 대전 | B103: 1250516 | C103: 56358 | D103: 342509 | AI103: 851649
A104: 청주 | B104: 537984 | C104: 21075 | D104: 133589 | AI104: 383320
... A111: 제주 | B111: 263759 | C111: 12991 | D111: 72559 | AI111: 178209

Sheet 5
A1: 3.인구와 사건과의 대비
A3: 최근 10년간의 인구변동과 사건추세를 대비하여 보면 표 2와 같고, 그 증감지수는 도표 6과 같다.
A5: 인구 및 전체사건수의 연도별비교-접수(표2)
A6: 구분 | B6: 인구 | D6: 전체사건 | F6: 소송사건 | J6: 비송사건 (등기,가족관계등록,공탁)
F7: 본안사건 | H7: 본안외사건
A8: 연도 | B8: 인구수 | C8: 지수 | D8: 사건수 | E8: 지수 | F8: 사건수 | G8: 지수 | H8: 사건수 | I8: 지수 | J8: 사건수 | K8: 지수
A9: 2013 | B9: 51141000 | C9: 100 | D9: 18466987 | E9: 100 | F9: 1605623 | G9: 100 | H9: 4985097 | I9: 100 | J9: 11876267 | K9: 100
A10: 2014 | B10: 51327000 | C10: 100.3637 | D10: 18986585 | E10: 102.81366 | F10: 1657385 | G10: 103.2238 | H10: 4843459 | I10: 97.158771 | J10: 12485741 | K10: 105.13187
A11: 2015 | B11: 51529000 | C11: 100.75869 | D11: 20609851 | E11: 111.60376 | F11: 1525846 | G11: 95.031399 | H11: 4835939 | I11: 97.007922 | J11: 14248066 | K11: 119.97091
A12: 2016 | B12: 51696000 | C12: 101.08523 | D12: 18978570 | E12: 102.77026 | F12: 1523108 | G12: 94.860873 | H12: 5224405 | I12: 104.80047 | J12: 12231057 | K12: 102.98739
A13: 2017 | B13: 51778000 | C13: 101.24558 | D13: 18069526 | E13: 97.847721 | F13: 1555602 | G13: 96.884636 | H13: 5187181 | I13: 104.05376 | J13: 11326743 | K13: 95.372923
A14: 2018 | B14: 51826000 | C14: 101.33943 | D14: 17651498 | E14: 95.584071 | F14: 1462714 | G14: 91.099467 | H14: 5122866 | I14: 102.76362 | J14: 11065918 | K14: 93.176736
A15: 2019 | B15: 51849000 | C15: 101.38441 | D15: 17720328 | E15: 95.95679 | F15: 1461440 | G15: 91.020121 | H15: 5172904 | I15: 103.76737 | J15: 11085984 | K15: 93.345695
A16: 2020 | B16: 51829000 | C16: 101.3453 | D16: 18838150 | E16: 102.00987 | F16: 1448551 | G16: 90.21738 | H16: 5230682 | I16: 104.92638 | J16: 12158917 | K16: 102.37996
A17: 2021 | B17: 51638000 | C17: 100.97182 | D17: 17884639 | E17: 96.846546 | F17: 1297441 | G17: 80.80608 | H17: 4994026 | I17: 100.17911 | J17: 11593172 | K17: 97.616296
A18: 2022 | B18: 51439000 | C18: 100.5827 | D18: 16023852 | E18: 86.770257 | F18: 1221301 | G18: 76.063995 | H18: 4946011 | I18: 99.215943 | J18: 9856540 | K18: 82.993587
A19: 주 : 1.인구수는 통계청 홈페이지(kosis.kr) 주민등록인구에 의한 것임(1,000미만은 버림)
A20: 2.비송사건 중 등기사건은 등·초본발급건수를 제외한 등기신청사건만을 파악함
A22: 제1심 사건에 대한 인구대비(표3)
A23: 구분 | C23: 소 송 사 건
B24: 총사건 | C24: 소송사건 | D24: 본안사건 | H24: 본안외사건 | I24: 비송사건
A25: 연도 | B25: 총인구 | C25: 총인구 | D25: 본안계 | E25: 민사 | F25: 가사 | G25: 형사 | H25: 총인구 | I25: 총인구
A26: 2013 | B26: 0.3566 | C26: 0.1244 | D26: 0.0281 | E26: 0.0214 | F26: 0.001 | G26: 0.0053 | H26: 0.0963 | I26: 0.2322
A27: 2014 | B27: 0.365 | C27: 0.1218 | D27: 0.0287 | E27: 0.0222 | F27: 0.001 | G27: 0.0052 | H27: 0.093 | I27: 0.2433
A28: 2015 | B28: 0.3949 | C28: 0.1184 | D28: 0.0259 | E28: 0.0195 | F28: 0.001 | G28: 0.005 | H28: 0.0925 | I28: 0.2765
A29: 2016 | B29: 0.3618 | C29: 0.1252 | D29: 0.0255 | E29: 0.0188 | F29: 0.001 | G29: 0.0053 | H29: 0.0997 | I29: 0.2366
A30: 2017 | B30: 0.3436 | C30: 0.1249 | D30: 0.0261 | E30: 0.0197 | F30: 0.0009 | G30: 0.0051 | H30: 0.0988 | I30: 0.2188
A31: 2018 | B31: 0.3353 | C31: 0.1218 | D31: 0.0245 | E31: 0.0185 | F31: 0.0009 | G31: 0.0046 | H31: 0.0973 | I31: 0.2135
A32: 2019 | B32: 0.33628549 | C32: 0.12247616 | D32: 0.024424193 | E32: 0.018314475 | F32: 0.0009175338 | G32: 0.0047707939 | H32: 0.09805197 | I32: 0.21380933
A33: 2020 | B33: 0.35803953 | C33: 0.12344284 | D33: 0.024203524 | E33: 0.01787431 | F33: 0.00087263848 | G33: 0.0050222826 | H33: 0.09923932 | I33: 0.23459669
A34: 2021 | B34: 0.34139765 | C34: 0.11689263 | D34: 0.021485914 | E34: 0.015776197 | F34: 0.0008621229 | G34: 0.0043853839 | H34: 0.095406712 | I34: 0.22450502
A35: 2022 | B35: 0.30643291 | C35: 0.11481696 | D35: 0.019985813 | E35: 0.014466114 | F35: 0.00081583952 | G35: 0.004277996 | H35: 0.094831148 | I35: 0.19161595
A36: 주 : 이 표는 인구수에 대한 접수건수 대비임

Sheet 6
B3: 합계 | F3: 지수
C4: 인구 | D4: 전체사건 | E4: 본안사건 | F4: 인구 | G4: 전체사건 | H4: 본안사건
B5: 12 | C5: 50948000 | D5: 18020241 | E5: 1573652
B6: 13 | C6: 51141000 | D6: 18466987 | E6: 1605623 | F6: 100 | G6: 100 | H6: 100 | I6: 기준년도시작
B7: 14 | C7: 51327000 | D7: 18986585 | E7: 1657385 | F7: 100.3637 | G7: 102.81366 | H7: 103.2238
B8: 15 | C8: 51529000 | D8: 20609851 | E8: 1525846 | F8: 100.75869 | G8: 111.60376 | H8: 95.031399
B9: 16 | C9: 51696000 | D9: 18978570 | E9: 1523108 | F9: 101.08523 | G9: 102.77026 | H9: 94.860873
B10: 17 | C10: 51778000 | D10: 18069526 | E10: 1555602 | F10: 101.24558 | G10: 97.847721 | H10: 96.884636
B11: 18 | C11: 51826000 | D11: 17651498 | E11: 1462714 | F11: 101.33943 | G11: 95.584071 | H11: 91.099467
B12: 19 | C12: 51849000 | D12: 17720328 | E12: 1461440 | F12: 101.38441 | G12: 95.95679 | H12: 91.020121
B13: 20 | C13: 51829000 | D13: 18838150 | E13: 1448551 | F13: 101.3453 | G13: 102.00987 | H13: 90.21738
B14: 21 | C14: 51638000 | D14: 17884639 | E14: 1297441 | F14: 100.97182 | G14: 96.846546 | H14: 80.80608
B15: 22 | C15: 51439000 | D15: 16023852 | E15: 1221301 | F15: 100.5827 | G15: 86.770257 | H15: 76.063995
A23: 각종 사건별로 제1심 사건에 대한 인구수를 연도별로 비교하여 보면 표 3과 같다. 2022년도의 경우 전체사건으로 볼 때 인구 100명당 사건 31건의 비율이 되고, 민사본안사건은 인구 1,000명당 사건 15건, 형사공판사건(치료감호사건 포함)은 인구 1,000명당 사건 4건의 비율이 된다. 인구와 사건수를 지역별로 비교하여 보면 표 4와 같다. 끝으로 민사본안사건과 형사공판사건의 주요 유형을 기준으로 법원별 인구수 대비 사건수 비교 내역을 수록하였다.
A25: 지역별 인구 및 사건수 비교(제1심)-접수(표4)
A26: 구분 | B26: 인구 | D26: 전체사건 | F26: 본안사건 | H26: 본안외사건 | J26: 비송사건
A27: 지역 | B27: 인구수 | C27: 비율 | D27: 건수 | E27: 비율 | F27: 건수 | G27: 비율 | H27: 건수 | I27: 비율 | J27: 건수 | K27: 비율
A28: 합 계 | B28: 51439038 | C28: 100 | D28: 15762614 | E28: 100 | F28: 1028051 | G28: 100 | H28: 4878023 | I28: 100 | J28: 9856540 | K28: 100
A29: 서울중앙지방법원관내 | B29: 2062591 | C29: 4.0097776 | D29: 1407326 | E29: 8.9282526 | F29: 236071 | G29: 22.962966 | H29: 621821 | I29: 12.747398 | J29: 549434 | K29: 5.574309
A30: 서울동부지방법원관내 | B30: 1737284 | C30: 3.3773649 | D30: 364910 | E30: 2.3150348 | F30: 42063 | G30: 4.0915285 | H30: 141495 | I30: 2.9006628 | J30: 181352 | K30: 1.8399154
A31: 서울남부지방법원관내 | B31: 2010679 | C31: 3.9088581 | D31: 550984 | E31: 3.4955116 | F31: 64991 | G31: 6.3217681 | H31: 204513 | I31: 4.1925387 | J31: 281480 | K31: 2.8557689
A32: 서울북부지방법원관내 | B32: 2261447 | C32: 4.3963633 | D32: 391525 | E32: 2.4838837 | F32: 30368 | G32: 2.9 | H32: 147796 | I32: 3.029834 | J32: 213361 | K32: 2.1646643
A33: 서울서부지방법원관내 | B33: 1356371 | C33: 2.6368514 | D33: 339126 | E33: 2.1514579 | F33: 29736 | G33: 2.8924635 | H33: 134830 | I33: 2.7640296 | J33: 174560 | K33: 1.7710069
A34: 의정부지방법원관내 | B34: 3589775 | C34: 6.9786978 | D34: 1065086 | E34: 6.7570392 | F34: 48129 | G34: 4.6815771 | H34: 292647 | I34: 5.9992952 | J34: 724310 | K34: 7.3485219
A35: 인천지방법원관내 | B35: 4241709 | C35: 8.3 | D35: 1279533 | E35: 8.1175178 | F35: 70191 | G35: 6.8275796 | H35: 404099 | I35: 8.2840733 | J35: 805243 | K35: 8.1696315
A36: 수원지방법원관내 | B36: 8767518 | C36: 17.044483 | D36: 2491569 | E36: 15.806826 | F36: 124054 | G36: 12.066911 | H36: 679117 | I36: 13.921972 | J36: 1688398 | K36: 17.129723
A37: 춘천지방법원관내 | B37: 1494242 | C37: 2.9048794 | D37: 537293 | E37: 3.4086542 | F37: 20486 | G37: 1.9927027 | H37: 123318 | I37: 2.5280324 | J37: 393489 | K37: 3.9921615
A38: 대전지방법원관내 | B38: 3952700 | C38: 7.6842417 | D38: 1250516 | E38: 7.9334303 | F38: 56358 | G38: 5.4820238 | H38: 342509 | I38: 7.0214716 | J38: 851649 | K38: 8.6404458
A39: 청주지방법원관내 | B39: 1595058 | C39: 3.1008706 | D39: 537984 | E39: 3.413038 | F39: 21075 | G39: 2.0499956 | H39: 133589 | I39: 2.738589 | J39: 383320 | K39: 3.8889915
... A46: 제주지방법원관내 | B46: 678159 | C46: 1.3183742 | D46: 263759 | E46: 1.6733202 | F46: 12991 | G46: 1.2636533 | H46: 72559 | I46: 1.4874674 | J46: 178209 | K46: 1.808028
A47: 주 : 1. 지역인구수는 각급 법원의 설치와 관할구역에 관한 법률에 의한 관할법원의 관내지역 인구수를 합한 것임
A48: 2. 서울중앙지방법원관내 사건수는 서울중앙지방법원과 서울행정법원, 서울가정법원, 서울회생법원의 사건수를 합산 기재함
A49: 3. 특허법원사건 872건은 제외함

Sheet 7
B1: [ 제1심 민사본안사건 주요 유형의 법원별 인구수 대비 사건수 비교 ]
B7: 매매대금 접수 사건수
B8: 서울남부지방법원관내 | C8: 0.21584748 | I8: 대여금 접수 사건수
B9: 인천지방법원관내 | C9: 0.2251451 | I9: 부산지방법원관내 | J9: 0.39513993
B10: 수원지방법원관내 | C10: 0.22697416 | I10: 제주지방법원관내 | J10: 0.40845878
B11: 서울동부지방법원관내 | C11: 0.22966884 | I11: 서울동부지방법원관내 | J11: 0.43919129
B12: 서울중앙지방법원관내 | C12: 0.3704079 | I12: 서울남부지방법원관내 | J12: 0.66196544
I13: 서울중앙지방법원관내 | J13: 1.5373867
B28: 구상금 접수 사건수
J29: 손해배상 접수 사건수
B30: 인천지방법원관내 | C30: 0.10349602 | J30: 부산지방법원관내 | K30: 0.54312903
B31: 부산지방법원관내 | C31: 0.12357542 | J31: 서울서부지방법원관내 | K31: 0.62593494
B32: 광주지방법원관내 | C32: 0.1345134 | J32: 서울남부지방법원관내 | K32: 0.66843091
B33: 서울남부지방법원관내 | C33: 0.16859976 | J33: 서울동부지방법원관내 | K33: 0.68555285
B34: 서울중앙지방법원관내 | C34: 2.0382131 | J34: 서울중앙지방법원관내 | K34: 2.9579301

Sheet 8
B1: [ 제1심 형사공판사건 주요 유형의 법원별 인구수 대비 사건수 비교 ]
C7: 폭행범죄
B8: 5 | C8: 부산지방법원 | D8: 0.55669218 | J8: 경제범죄
B9: 4 | C9: 울산지방법원 | D9: 0.55720387 | I9: 5 | J9: 울산지방법원 | K9: 1.2359547
B10: 3 | C10: 창원지방법원 | D10: 0.57197507 | I10: 4 | J10: 인천지방법원 | K10: 1.2638774
B11: 2 | C11: 서울중앙지방법원 | D11: 0.59391319 | I11: 3 | J11: 제주지방법원 | K11: 1.2666646
B12: 1 | C12: 제주지방법원 | D12: 0.70927319 | I12: 2 | J12: 부산지방법원 | K12: 1.431365
I13: 1 | J13: 서울중앙지방법원 | K13: 1.7022279
A22: 주 : 폭행범죄는 형법의 상해와 폭행의 죄, 강도의 죄, 특별법의 폭력행위등 처벌에 관한 법률 위반에 해당되는 죄임 | H22: 주 : 경제범죄는 형법의 사기의 죄, 횡령과 배임의 죄, 절도의 죄, 특별법의 독점규제 및 공정거래에 관한 법률, 특정경제범죄가중처벌 등에 관한 법률 위반에 해당되는 죄임
D29: 교통범죄
C30: 5 | D30: 광주지방법원 | E30: 1.2509438
C31: 4 | D31: 청주지방법원 | E31: 1.2513652 | K31: 성범죄
C32: 3 | D32: 창원지방법원 | E32: 1.2594385 | J32: 5 | K32: 인천지방법원 | L32: 0.34090033
C33: 2 | D33: 제주지방법원 | E33: 1.3949531 | J33: 4 | K33: 부산지방법원 | L33: 0.3580673
C34: 1 | D34: 춘천지방법원 | E34: 1.6449812 | J34: 3 | K34: 서울남부지방법원 | L34: 0.36355878
J35: 2 | K35: 제주지방법원 | L35: 0.36717053
J36: 1 | K36: 서울중앙지방법원 | L36: 0.61427593
A43: 주 : 교통범죄는 특별법의 교통사고처리특례법, 도로교통법, 특정범죄가중처벌에 관한 법률(도주차량, 위험운전치사상, 운전자폭행 등)위반에 해당되는 죄임 | H43: 주 : 성범죄는 형법의 강간과 추행의 죄, 특별법의 성매매알선등 행위의 처벌에 관한 법률, 성매매방지 및 피해자보호 등에 관한 법률, 성폭력범죄의 처벌 등에 관한 특례법, 아동·청소년의 성보호에 관한 법률 위반에 해당되는 죄임

Sheet 9
A1: 4. 법관 업무량
A3: 가동법관 수를 기준한 법관 1인당 처리건수는 표 5와 같다
A5: 법관 1인당 처리건수 (표 5)
A6: 법원 | B6: 대법원 | D6: 고등법원 | F6: 지방법원
A7: 구분 | B7: 가동법관 수 | C7: 법관 1인당 처리건수 | D7: 가동법관 수 | E7: 법관 1인당 처리건수 | F7: 가동법관 수 | G7: 법관 1인당 처리건수
A8: 본안사건 | B8: 12 | C8: 4038.3 | D8: 341 | E8: 95.7 | F8: 2313 | G8: 503.4
A9: 주 : 1. 가동법관 수는 2022.12.31. 현재 각급법원에 배치된 법관 수임
A10: 2. 대법원 가동법관 수에는 대법원장, 법원행정처장 제외함

Sheet 항소심 처리
A2: 구분 | B2: 총계 | C2: 소 송 사 건 | K2: 비 송 사 건
A3: 법원 | C3: 합계 | D3: 민사 | E3: 가사 | F3: 행정 | G3: 특허 | H3: 선거 | I3: 형사 | J3: 소년 | K3: 합계 | L3: 등기 | M3: 가족관계등록비송 | N3: 공탁
A4: 총계 | B4: =SUM(B5,B6,B7) -> 16040439 | C4: =SUM(C5,C6,C7) -> 6194011 | D4: =SUM(D5,D6,D7) -> 4274201 | E4: =SUM(E5,E6,E7) -> 176439 | F4: =SUM(F5,F6,F7) -> 49613 | G4: =SUM(G5,G6,G7) -> 1275 | H4: =SUM(H5,H6,H7) -> 171 | I4: =SUM(I5,I6,I7) -> 1563150 | ... N4: =SUM(N5,N6,N7) -> 172926
A5: 대법원 | B5: =SUM(C5,K5) -> 64394 | C5: =SUM(D5:J5) -> 64394 | D5: =SUM(D15:E15) -> 30953 | E5: =SUM(F15:G15) -> 1184 | F5: =SUM(H15:I15) -> 5988 | G5: =SUM(J15:K15) -> 181 | H5: =SUM(L15:M15) -> 153 | I5: =SUM(N15:P15,V15,W15,X15) -> 25753 | J5: =SUM(Q15:U15) -> 182 | K5: 0 | L5: 0 | M5: 0 | N5: 0
A6: 고등법원합계 | B6: =SUM(C6,K6) -> 58984 | C6: =SUM(D6:J6) -> 58984 | D6: =SUM(D20:E20) -> 21236 | E6: =SUM(F20:G20) -> 1933 | F6: =SUM(H20:I20) -> 9836 | G6: =SUM(J20:K20) -> 1094 | H6: =SUM(L20:M20) -> 3 | I6: =SUM(N20:P20) -> 24879 | J6: =SUM(Q20:R20) -> 3 | K6: 0 | L6: 0 | M6: 0 | N6: 0
A7: 지방법원합계 | B7: =SUM(B8:B9) -> 15917061 | C7: =SUM(C8:C9) -> 6070633 | D7: =SUM(D32:E32,'제1심 처리'!E6:M6) -> 4222012 | E7: =SUM(E8:E9) -> 173322 | F7: =SUM(F8:F9) -> 33789 | G7: =SUM(G8:G9) -> 0 | H7: =SUM(H8:H9) -> 15 | I7: =SUM(I8:I9) -> 1512518 | J7: =SUM(J8:J9) -> 128977 | K7: =SUM(L7:N7) -> 9846428 | L7: =SUM(L8:L9) -> 9433210 | M7: =SUM(M8:M9) -> 240292 | N7: =SUM(N8:N9) -> 172926
A8: 항소심계 | B8: =SUM(C8,K8) -> 127167 | C8: =SUM(D8:J8) -> 127167 | D8: =SUM(D32:E32) -> 57499 | E8: =SUM(F32:G32) -> 4119 | F8: 0 | G8: 0 | H8: 0 | I8: =SUM(H32:I32,O32,P32,Q32) -> 63375 | J8: =SUM(J32:N32) -> 2174 | K8: =SUM(L8:N8) -> 0 | L8: 0 | M8: 0 | N8: 0
A9: 제1심계 | B9: =SUM(C9,K9) -> 15789894 | C9: =SUM(D9:J9) -> 5943466 | D9: =SUM('제1심 처리'!E6:M6) -> 4164513 | E9: =SUM('제1심 처리'!N6:Q6) -> 169203 | F9: =SUM('제1심 처리'!R6:S6)-H9 -> 33789 | G9: 0 | H9: 15 | I9: =SUM('제1심 처리'!T6:Z6,'제1심 처리'!AF6:AH6) -> 1449143 | J9: =SUM('제1심 처리'!AA6:AE6) -> 126803 | K9: =SUM(L9:N9) -> 9846428 | L9: ='제1심 처리'!AJ6 -> 9433210 | M9: ='제1심 처리'!AK1 -> 240292 | N9: ='제1심 처리'!AL6 -> 172926
A10: 주 : 감치·과태료 59,866건(상고심 8건, 항소심 37건, 제1심 59,821건)과 인신보호 1,158건(상고심 13건, 지법항소심 64건, 제1심 1,081건), 성매매관련 167건(지법항소심 1건, 제1심 166건)은 형사란에, 가정보호 47,622건(상고심 79건, 항소심 1,034건, 제1심 46,509건), 피해자보호명령 3,087건(상고심 19건, 지법항소심 234건, 제1심 2,834건), 아동보호명령 19,945건(상고심 48건, 항소심 558건, 제1심 19,339건), 피해아동보호명령 1,712건(상고심 22건, 지법항소심 130건, 제1심 1,560건)은 소년란에 각각 합산하였음
A12: 나.대법원
A13: 구분 | B13: 합 계 | D13: 민 사 | F13: 가 사 | H13: 행 정 | J13: 특 허 | L13: 선 거 | N13: 형 사 | Q13: 소년 | R13: 가정보호 | S13: 피해자보호명령 | T13: 아동보호 | U13: 피해아동보호 | V13: 인신보호 | W13: 성매매관련 보호
A14: 법원 | B14: 본안 | C14: 본안외 | D14: 본안 | E14: 본안외 | F14: 본안 | G14: 본안외 | H14: 본안 | I14: 본안외 | J14: 본안 | K14: 본안외 | L14: 본안 | M14: 본안외 | N14: 공판 | O14: 치료감호 | P14: 본안외 | Z14: 법원 | AA14: 합계 | AB14: 형사신청 | AC14: 영장 | AD14: 부착명령 | AE14: 보호관찰 | AF14: 치료명령 | AG14: 재항고 | AH14: 감치·과태료
A15: 대법원 | B15: =D15+F15+H15+J15+L15+N15+O15 -> 48460 | C15: =SUM(E15,G15,I15,K15,M15,P15:W15) -> 15934 | D15: 23924 | E15: 7029 | F15: 706 | G15: 478 | H15: 4172 | I15: 1816 | J15: 138 | K15: 43 | L15: 71 | M15: 82 | N15: 19432 | O15: 17 | P15: 6291 | Q15: 14 | R15: 79 | S15: 19 | T15: 48 | U15: 22 | V15: 13 | W15: 0 | Z15: 대법원 | AA15: =SUM(AB15:AH15) -> 6291 | AB15: 1059 | AC15: 13 | AD15: 188 | AE15: 76 | AF15: 1 | AG15: 4946 | AH15: 8
A17: 다.고등법원
A18: 구분 | B18: 합 계 | D18: 민 사 | F18: 가 사 | H18: 행 정 | J18: 특 허 | L18: 선 거 | N18: 형 사 | Q18: 가정보호 | R18: 아동보호
A19: 법원 | B19: 본안 | C19: 본안외 | D19: 본안 | E19: 본안외 | F19: 본안 | G19: 본안외 | H19: 본안 | I19: 본안외 | J19: 본안 | K19: 본안외 | L19: 본안 | M19: 본안외 | N19: 공판 | O19: 치료감호 | P19: 본안외 | Z19: 법원 | AA19: 합계 | AB19: 형사신청 | AC19: 영장 | AD19: 부착명령 | AE19: 보호관찰 | AF19: 치료명령 | AG19: 항고 | AH19: 준항고 | AI19: 감치·과태료
A20: 합계 | B20: =SUM(B21:B27) -> 32633 | C20: =SUM(C21:C27) -> 26351 | D20: =SUM(D21:D27) -> 14015 | E20: =SUM(E21:E27) -> 7221 | F20: =SUM(F21:F27) -> 1163 | G20: =SUM(G21:G27) -> 770 | H20: =SUM(H21:H27) -> 7559 | I20: =SUM(I21:I27) -> 2277 | ... R20: =SUM(R21:R27) -> 1 | Z20: 합계 | AA20: =SUM(AB20:AI20) -> 15598 | AB20: =SUM(AB21:AB26) -> 14068 | AC20: =SUM(AC21:AC26) -> 317 | AD20: =SUM(AD21:AD26) -> 534 | AE20: =SUM(AE21:AE26) -> 285 | AF20: =SUM(AF21:AF26) -> 3 | AG20: =SUM(AG21:AG26) -> 388 | AH20: =SUM(AH21:AH26) -> 1 | AI20: =SUM(AI21:AI26) -> 2
A21: 서울고등법원 | B21: =SUM(D21,F21,H21,L21,N21,O21,J21) -> 17594 | C21: =SUM(E21,G21,I21,K21,M21,P21:R21) -> 10854 | D21: 8233 | E21: 3896 | F21: 492 | G21: 403 | H21: 4903 | I21: 1258 | J21: 0 | K21: 0 | L21: 1 | M21: 0 | N21: 3929 | O21: 36 | P21: 5297 | Q21: 0 | R21: 0 | Z21: 서울고등법원 | AA21: =SUM(AB21:AI21) -> 5297 | AB21: 4705 | AC21: 137 | AD21: 185 | AE21: 96 | AF21: 1 | AG21: 172 | AH21: 1 | AI21: 0
A22: 대전고등법원 | B22: =SUM(D22,F22,H22,L22,N22,O22,J22) -> 2439 | C22: =SUM(E22,G22,I22,K22,M22,P22:R22) -> 2058 | D22: 879 | E22: 431 | F22: 108 | G22: 57 | H22: 540 | I22: 263 | J22: 0 | K22: 0 | L22: 0 | M22: 0 | N22: 899 | O22: 13 | P22: 1307 | Q22: 0 | R22: 0 | Z22: 대전고등법원 | AA22: =SUM(AB22:AI22) -> 1307 | AB22: 1116 | AC22: 55 | AD22: 73 | AE22: 23 | AF22: 2 | AG22: 37 | AH22: 0 | AI22: 1
A23: 대구고등법원 | B23: =SUM(D23,F23,H23,L23,N23,O23,J23) -> 1963 | C23: =SUM(E23,G23,I23,K23,M23,P23:R23) -> 2181 | D23: 813 | E23: 421 | F23: 64 | G23: 41 | H23: 378 | I23: 108 | J23: 0 | K23: 0 | L23: 0 | M23: 0 | N23: 699 | O23: 9 | P23: 1611 | Q23: 0 | R23: 0 | Z23: 대구고등법원 | AA23: =SUM(AB23:AI23) -> 1611 | AB23: 1486 | AC23: 27 | AD23: 37 | AE23: 37 | AF23: 0 | AG23: 24 | AH23: 0 | AI23: 0
A24: 부산고등법원 | B24: =SUM(D24,F24,H24,L24,N24,O24,J24) -> 3446 | C24: =SUM(E24,G24,I24,K24,M24,P24:R24) -> 5113 | D24: 1401 | E24: 715 | F24: 169 | G24: 106 | H24: 609 | I24: 279 | J24: 0 | K24: 0 | L24: 1 | M24: 1 | N24: 1261 | O24: 5 | P24: 4012 | Q24: 0 | R24: 0 | Z24: 부산고등법원 | AA24: =SUM(AB24:AI24) -> 4012 | AB24: 3710 | AC24: 46 | AD24: 103 | AE24: 91 | AF24: 0 | AG24: 61 | AH24: 0 | AI24: 1
A25: 광주고등법원 | B25: =SUM(D25,F25,H25,L25,N25,O25,J25) -> 2663 | C25: =SUM(E25,G25,I25,K25,M25,P25:R25) -> 2303 | D25: 939 | E25: 594 | F25: 87 | G25: 51 | H25: 633 | I25: 191 | J25: 0 | K25: 0 | L25: 0 | M25: 0 | N25: 994 | O25: 10 | P25: 1467 | Q25: 0 | R25: 0 | Z25: 광주고등법원 | AA25: =SUM(AB25:AI25) -> 1467 | AB25: 1308 | AC25: 31 | AD25: 70 | AE25: 20 | AF25: 0 | AG25: 38 | AH25: 0 | AI25: 0
A26: 수원고등법원 | B26: =SUM(D26,F26,H26,L26,N26,O26,J26) -> 3809 | C26: =SUM(E26,G26,I26,K26,M26,P26:R26) -> 3293 | D26: 1644 | E26: 1096 | F26: 243 | G26: 112 | H26: 496 | I26: 178 | J26: 0 | K26: 0 | L26: 0 | M26: 0 | N26: 1419 | O26: 7 | P26: 1904 | Q26: 2 | R26: 1 | Z26: 수원고등법원 | AA26: =SUM(AB26:AI26) -> 1904 | AB26: 1743 | AC26: 21 | AD26: 66 | AE26: 18 | AF26: 0 | AG26: 56 | AH26: 0 | AI26: 0
A27: 특허법원 | B27: =SUM(D27,F27,H27,L27,N27,O27,J27) -> 719 | C27: =SUM(E27,G27,I27,K27,M27,P27:R27) -> 549 | D27: 106 | E27: 68 | F27: 0 | G27: 0 | H27: 0 | I27: 0 | J27: 613 | K27: 481 | L27: 0 | M27: 0 | N27: 0 | O27: 0 | P27: 0 | Q27: 0 | R27: 0
A29: 라.지방법원(항소심)
A30: 구분 | B30: 합계 | D30: 민사 | F30: 가사 | H30: 형사 | J30: 소년 | K30: 가정 보호 | L30: 피해자 보호 명령 | M30: 아동 보호 | N30: 피해아동 보호명령 | O30: 인신 보호 | P30: 성매매 관련 보호 | Z30: 법원 | AA30: 합계 | AB30: 항고 | AC30: 준항고 | AD30: 감치·과태료
A31: 법원 | B31: 본안 | C31: 본안외 | D31: 본안 | E31: 본안외 | F31: 본안 | G31: 본안외 | H31: 본안 | I31: 본안외 | Z31: 합계 | AA31: =SUM(AB31:AD31) -> 2475 | AB31: =SUM(AB32:AB51) -> 2278 | AC31: =SUM(AC32:AC51) -> 162 | AD31: =SUM(AD32:AD51) -> 35
A32: 합계 | B32: =SUM(B33:B52) -> 108441 | C32: =SUM(C33:C52) -> 18726 | D32: =SUM(D33:D52) -> 44862 | E32: =SUM(E33:E52) -> 12637 | F32: =SUM(F33:F52) -> 2744 | G32: =SUM(G33:G52) -> 1375 | H32: =SUM(H33:H52) -> 60835 | I32: =SUM(I33:I52) -> 2475 | ... P32: =SUM(P33:P52) -> 1 | Z32: 서울중앙지방법원 | AA32: =SUM(AB32:AD32) -> 185 | AB32: 180 | AC32: 4 | AD32: 1
A33: 서울중앙지방법원 | B33: =SUM(H33,F33,D33) -> 12714 | C33: =SUM(E33,G33,I33,J33:P33) -> 807 | D33: 8646 | E33: 622 | F33: 0 | G33: 0 | H33: 4068 | I33: 185 | J33: 0 | K33: 0 | L33: 0 | M33: 0 | N33: 0 | O33: 0 | P33: 0 | Z33: 서울가정법원 | AA33: =SUM(AB33:AD33) -> 6 | AB33: 0 | AC33: 0 | AD33: 6
A34: 서울가정법원 | B34: =SUM(H34,F34,D34) -> 417 | C34: =SUM(E34,G34,I34,J34:P34) -> 655 | D34: 0 | E34: 0 | F34: 417 | G34: 160 | H34: 0 | I34: 6 | J34: 35 | K34: 261 | L34: 68 | M34: 97 | N34: 28 | O34: 0 | P34: 0 | Z34: 서울회생법원 | AA34: =SUM(AB34:AD34) -> 0 | AB34: 0 | AC34: 0 | AD34: 0
A35: 서울회생법원 | B35: =SUM(H35,F35,D35) -> 1 | C35: =SUM(E35,G35,I35,J35:P35) -> 564 | D35: 1 | E35: 564 | F35: 0 | G35: 0 | H35: 0 | I35: 0 | J35: 0 | K35: 0 | L35: 0 | M35: 0 | N35: 0 | O35: 0 | P35: 0 | Z35: 서울동부지방법원 | AA35: =SUM(AB35:AD35) -> 71 | AB35: 62 | AC35: 8 | AD35: 1
A36: 서울동부지방법원 | B36: =SUM(H36,F36,D36) -> 3217 | C36: =SUM(E36,G36,I36,J36:P36) -> 359 | D36: 1440 | E36: 277 | F36: 0 | G36: 9 | H36: 1777 | I36: 71 | J36: 0 | K36: 0 | L36: 0 | M36: 0 | N36: 0 | O36: 2 | P36: 0 | Z36: 서울남부지방법원 | AA36: =SUM(AB36:AD36) -> 111 | AB36: 106 | AC36: 5 | AD36: 0
A37: 서울남부지방법원 | B37: =SUM(H37,F37,D37) -> 4770 | C37: =SUM(E37,G37,I37,J37:P37) -> 440 | D37: 2213 | E37: 322 | F37: 0 | G37: 5 | H37: 2557 | I37: 111 | J37: 0 | K37: 0 | L37: 0 | M37: 0 | N37: 0 | O37: 2 | P37: 0 | Z37: 서울북부지방법원 | AA37: =SUM(AB37:AD37) -> 119 | AB37: 112 | AC37: 6 | AD37: 1
A38: 서울북부지방법원 | B38: =SUM(H38,F38,D38) -> 3418 | C38: =SUM(E38,G38,I38,J38:P38) -> 412 | D38: 1373 | E38: 282 | F38: 0 | G38: 8 | H38: 2045 | I38: 119 | J38: 0 | K38: 0 | L38: 0 | M38: 0 | N38: 0 | O38: 3 | P38: 0 | Z38: 서울서부지방법원 | AA38: =SUM(AB38:AD38) -> 81 | AB38: 77 | AC38: 4 | AD38: 0
A39: 서울서부지방법원 | B39: =SUM(H39,F39,D39) -> 2459 | C39: =SUM(E39,G39,I39,J39:P39) -> 342 | D39: 1153 | E39: 253 | F39: 0 | G39: 7 | H39: 1306 | I39: 81 | J39: 0 | K39: 0 | L39: 0 | M39: 0 | N39: 0 | O39: 1 | P39: 0 | Z39: 의정부지방법원 | AA39: =SUM(AB39:AD39) -> 126 | AB39: 122 | AC39: 3 | AD39: 1
A40: 의정부지방법원 | B40: =SUM(H40,F40,D40) -> 6764 | C40: =SUM(E40,G40,I40,J40:P40) -> 1327 | D40: 2847 | E40: 1032 | F40: 160 | G40: 64 | H40: 3757 | I40: 126 | J40: 16 | K40: 46 | L40: 16 | M40: 19 | N40: 5 | O40: 3 | P40: 0 | Z40: 인천지방법원 | AA40: =SUM(AB40:AD40) -> 248 | AB40: 225 | AC40: 19 | AD40: 4
A41: 인천지방법원 | B41: =SUM(H41,F41,D41) -> 8210 | C41: =SUM(E41,G41,I41,J41:P41) -> 1781 | D41: 2716 | E41: 1183 | F41: 244 | G41: 128 | H41: 5250 | I41: 248 | J41: 12 | K41: 99 | L41: 21 | M41: 75 | N41: 9 | O41: 6 | P41: 0 | Z41: 수원지방법원 | AA41: =SUM(AB41:AD41) -> 324 | AB41: 280 | AC41: 35 | AD41: 9
A42: 수원지방법원 | B42: =SUM(H42,F42,D42) -> 15573 | C42: =SUM(E42,G42,I42,J42:P42) -> 2994 | D42: 5783 | E42: 1964 | F42: 523 | G42: 248 | H42: 9267 | I42: 324 | J42: 31 | K42: 209 | L42: 42 | M42: 140 | N42: 26 | O42: 10 | P42: 0 | Z42: 춘천지방법원 | AA42: =SUM(AB42:AD42) -> 53 | AB42: 43 | AC42: 7 | AD42: 3
A43: 춘천지방법원 | B43: =SUM(H43,F43,D43) -> 3905 | C43: =SUM(E43,G43,I43,J43:P43) -> 632 | D43: 1415 | E43: 494 | F43: 95 | G43: 43 | H43: 2395 | I43: 53 | J43: 7 | K43: 20 | L43: 6 | M43: 7 | N43: 1 | O43: 1 | P43: 0 | Z43: 대전지방법원 | AA43: =SUM(AB43:AD43) -> 159 | AB43: 146 | AC43: 11 | AD43: 2
A44: 대전지방법원 | B44: =SUM(H44,F44,D44) -> 6863 | C44: =SUM(E44,G44,I44,J44:P44) -> 1310 | D44: 2640 | E44: 890 | F44: 160 | G44: 112 | H44: 4063 | I44: 159 | J44: 28 | K44: 46 | L44: 19 | M44: 33 | N44: 17 | O44: 6 | P44: 0 | Z44: 청주지방법원 | AA44: =SUM(AB44:AD44) -> 73 | AB44: 69 | AC44: 4 | AD44: 0
...

Sheet 제1심 처리
A1: 지방법원(제1심) | B1: =SUM(B7:B17,B19:B21,B23:B29,B31:B35,B37:B43,B45:B48,B50:B59,B61:B64,B66:B67,B69:B74,B76:B81,B83:B86,B88) -> 15789894 | C1: =SUM(C7:C17,C19:C21,C23:C29,C31:C35,C37:C43,C45:C48,C50:C59,C61:C64,C66:C67,C69:C74,C76:C81,C83:C86,C88) -> 1055902 | D1: =SUM(D7:D17,D19:D21,D23:D29,D31:D35,D37:D43,D45:D48,D50:D59,D61:D64,D66:D67,D69:D74,D76:D81,D83:D86,D88) -> 4887564 | E1: =SUM(E7:E17,E19:E21,E23:E29,E31:E35,E37:E43,E45:E48,E50:E59,E61:E64,E66:E67,E69:E74,E76:E81,E83:E86,E88) -> 37595 | F1: =SUM(F7:F17,F19:F21,F23:F29,F31:F35,F37:F43,F45:F48,F50:F59,F61:F64,F66:F67,F69:F74,F76:F81,F83:F86,F88) -> 215273 | G1: =SUM(G7:G17,G19:G21,G23:G29,G31:G35,G37:G43,G45:G48,G50:G59,G61:G64,G66:G67,G69:G74,G76:G81,G83:G86,G88) -> 515031 | H1: =SUM(H7:H17,H19:H21,H23:H29,H31:H35,H37:H43,H45:H48,H50:H59,H61:H64,H66:H67,H69:H74,H76:H81,H83:H86,H88) -> 67260 | I1: =SUM(I7:I17,I19:I21,I23:I29,I31:I35,I37:I43,I45:I48,I50:I59,I61:I64,I66:I67,I69:I74,I76:I81,I83:I86,I88) -> 1039860 | ... AC1: =SUM(AC7:AC17,AC19:AC21,AC23:AC29,AC31:AC35,AC37:AC43,AC45:AC48,AC50:AC59,AC61:AC64,AC66:AC67,AC69:AC74,AC76:AC81,AC83:AC86,AC88) -> 2834 | AD1: =SUM(AD7:AD17,AD19:AD21,AD23:AD29,AD31:AD35,AD37:AD43,AD45:AD48,AD50:AD59,AD61:AD64,AD66:AD67,AD69:AD74,AD77:AD81,AD83:AD86,AD88) -> 19339 | AE1: =SUM(AE7:AE17,AE19:AE21,AE23:AE29,AE31:AE35,AE37:AE43,AE45:AE48,AE50:AE59,AE61:AE64,AE66:AE67,AE69:AE74,AE76:AE81,AE83:AE86,AE88) -> 1560 | AF1: =SUM(AF7:AF17,AF19:AF21,AF23:AF29,AF31:AF35,AF37:AF43,AF45:AF48,AF50:AF59,AF61:AF64,AF66:AF67,AF69:AF74,AF76:AF81,AF83:AF86,AF88) -> 1081 | AG1: =SUM(AG7:AG17,AG19:AG21,AG23:AG29,AG31:AG35,AG37:AG43,AG45:AG48,AG50:AG59,AG61:AG64,AG66:AG67,AG69:AG74,AG76:AG81,AG83:AG86,AG88) -> 166 | AH1: =SUM(AH7:AH17,AH19:AH21,AH23:AH29,AH31:AH35,AH37:AH43,AH45:AH48,AH50:AH59,AH61:AH64,AH66:AH67,AH69:AH74,AH76:AH81,AH83:AH86,AH88) -> 59821 | AI1: =SUM(AI7:AI17,AI19:AI21,AI23:AI29,AI31:AI35,AI37:AI43,AI45:AI48,AI50:AI59,AI61:AI64,AI66:AI67,AI69:AI74,AI76:AI81,AI83:AI86,AI88) -> 9846428 | AJ1: =SUM(AJ7:AJ17,AJ19:AJ21,AJ23:AJ29,AJ31:AJ35,AJ37:AJ43,AJ45:AJ48,AJ50:AJ59,AJ61:AJ64,AJ66:AJ67,AJ69:AJ74,AJ76:AJ81,AJ83:AJ86,AJ88) -> 9433210 | AK1: =SUM(AK7:AK17,AK19:AK21,AK23:AK29,AK31:AK35,AK37:AK43,AK45:AK48,AK50:AK59,AK61:AK64,AK66:AK67,AK69:AK74,AK76:AK81,AK83:AK86,AK88) -> 240292 | AL1: =SUM(AL7:AL17,AL19:AL21,AL23:AL29,AL31:AL35,AL37:AL43,AL45:AL48,AL50:AL59,AL61:AL64,AL66:AL67,AL69:AL74,AL76:AL81,AL83:AL86,AL88) -> 172926
A2: 구분 | B2: 총계 | C2: 소 송 사 건 | AI2: 비 송 사 건
C3: 합 계 | E3: 민 사 | N3: 가 사 | R3: 행정·선거 | T3: 형 사 | AA3: 소년 | AB3: 가정보호 | AC3: 피해자 보호 명령 | AD3: 아동 보호 | AE3: 피해아동보호명령 | AF3: 인신 보호 | AG3: 성매매 관련 보호 | AH3: 감치 과태료 | AI3: 합 계 | AJ3: 등 기 | AK3: 가족 관계 등록 | AL3: 공 탁
C4: 본안 | D4: 기타 (비송제외) | E4: 본 안 | H4: 본 안 외 | N4: 본안 | O4: 본안외 | R4: 본안 | S4: 본안외 | T4: 본 안 | W4: 본 안 외
A5: 법원 | E5: 합의 | F5: 단독 | G5: 소액 | H5: 조정 | I5: 독촉 | J5: 집행 | K5: 비송 | L5: 신청 | M5: 도산 | O5: 조정 | P5: 비송 | Q5: 신청 | T5: 합의 | U5: 단독 | V5: 치료감호 | W5: 즉결 | X5: 약식 | Y5: 영장 | Z5: 신청 | AN5: *2022년 업데이트 전
A6: 합 계 | B6: =SUM(AI6+D6+C6) -> 15789894 | C6: =SUM(C7:C14,C18,C22,C30,C36,C44,C49,C60,C65,C68,C75,C82,C87:C88) -> 1055902 | D6: =SUM(D7:D14,D18,D22,D30,D36,D44,D49,D60,D65,D68,D75,D82,D87:D88) -> 4887564 | E6: =SUM(E7:E14,E18,E22,E30,E36,E44,E49,E60,E65,E68,E75,E82,E87:E88) -> 37595 | F6: =SUM(F7:F14,F18,F22,F30,F36,F44,F49,F60,F65,F68,F75,F82,F87:F88) -> 215273 | G6: =SUM(G7:G14,G18,G22,G30,G36,G44,G49,G60,G65,G68,G75,G82,G87:G88) -> 515031 | H6: =SUM(H7:H14,H18,H22,H30,H36,H44,H49,H60,H65,H68,H75,H82,H87:H88) -> 67260 | I6: =SUM(I7:I14,I18,I22,I30,I36,I44,I49,I60,I65,I68,I75,I82,I87:I88) -> 1039860 | J6: =SUM(J7:J14,J18,J22,J30,J36,J44,J49,J60,J65,J68,J75,J82,J87:J88) -> 1226421 | ... AI6: =SUM(AI7:AI14,AI18,AI22,AI30,AI36,AI44,AI49,AI60,AI65,AI68,AI75,AI82,AI87:AI88) -> 9846428 | AJ6: 9433210 | AK6: 240292 | AL6: =SUM(AL7:AL14,AL18,AL22,AL30,AL36,AL44,AL49,AL60,AL65,AL68,AL75,AL82,AL87:AL88) -> 172926 | AN6: ㅁ 수정하면 폰트색 변경 할 것
A7: 서울중앙지방법원 | B7: =SUM(AI7+D7+C7) -> 1296721 | C7: =SUM(E7:G7,N7,R7,T7:V7) -> 226630 | D7: =SUM(H7:M7,O7:Q7,S7,W7:AH7) -> 533619 | E7: 9428 | F7: 41905 | G7: 162217 | H7: 12818 | I7: 309222 | J7: 46760 | K7: 6853 | L7: 81583 | M7: 0 | N7: 0 | O7: 0 | P7: 0 | Q7: 0 | R7: 0 | S7: 2 | T7: 1455 | U7: 11607 | V7: 18 | W7: 5532 | X7: 21651 | Y7: 40045 | Z7: 7588 | AA7: 0 | AB7: 0 | AC7: 0 | AD7: 0 | AE7: 0 | AF7: 16 | AG7: 0 | AH7: 1549 | AI7: =SUM(AJ7:AL7) -> 536472 | AJ7: 517072 | AK7: 0 | AL7: 19400
A8: 서울가정법원 | B8: =SUM(AI8+D8+C8) -> 59696 | C8: =SUM(E8:G8,N8,R8,T8:V8) -> 7917 | D8: =SUM(H8:M8,O8:Q8,S8,W8:AH8) -> 42769 | E8: 0 | F8: 0 | G8: 0 | H8: 0 | I8: 0 | J8: 0 | K8: 0 | L8: 0 | M8: 0 | N8: 7917 | O8: 2815 | P8: 17693 | Q8: 4660 | R8: 0 | S8: 0 | T8: 0 | U8: 0 | V8: 0 | W8: 0 | X8: 0 | Y8: 0 | Z8: 0 | AA8: 7549 | AB8: 6664 | AC8: 440 | AD8: 2426 | AE8: 266 | AF8: 0 | AG8: 54 | AH8: 202 | AI8: =SUM(AJ8:AL8) -> 9010 | AJ8: 0 | AK8: 9010 | AL8: 0 | AN8: 형사신청
A9: 서울행정법원 | B9: =SUM(AI9+D9+C9) -> 13084 | C9: =SUM(E9:G9,N9,R9,T9:V9) -> 8246 | D9: =SUM(H9:M9,O9:Q9,S9,W9:AH9) -> 4838 | E9: 0 | F9: 0 | G9: 0 | H9: 0 | I9: 0 | J9: 0 | K9: 0 | L9: 0 | M9: 0 | N9: 0 | O9: 0 | P9: 0 | Q9: 0 | R9: 8246 | S9: 4838 | T9: 0 | U9: 0 | V9: 0 | W9: 0 | X9: 0 | Y9: 0 | Z9: 0 | AA9: 0 | AB9: 0 | AC9: 0 | AD9: 0 | AE9: 0 | AF9: 0 | AG9: 0 | AH9: 0 | AI9: =SUM(AJ9:AL9) -> 0 | AJ9: 0 | AK9: 0 | AL9: 0 | AN9: 법원 | AO9: 합계 | AP9: 형사신청 | AQ9: 부착명령사건 | AR9: 보호관찰명령사건 | AS9: 치료명령사건
A10: 서울회생법원 | B10: =SUM(AI10+D10+C10) -> 39995 | C10: =SUM(E10:G10,N10,R10,T10:V10) -> 218 | D10: =SUM(H10:M10,O10:Q10,S10,W10:AH10) -> 39777 | E10: 218 | F10: 0 | G10: 0 | H10: 0 | K10: 0 | L10: 129 | M10: 39648 | N10: 0 | O10: 0 | P10: 0 | Q10: 0 | R10: 0 | S10: 0 | T10: 0 | U10: 0 | V10: 0 | W10: 0 | X10: 0 | Y10: 0 | Z10: 0 | AA10: 0 | AB10: 0 | AC10: 0 | AD10: 0 | AE10: 0 | AF10: 0 | AG10: 0 | AH10: 0 | AI10: =SUM(AJ10:AL10) -> 0 | AJ10: 0 | AK10: 0 | AL10: 0 | AN10: 합계 | AO10: =SUM(AP10,AQ10,AR10,AS10) -> 95548 | AP10: =SUM(AP11:AP15,AP19,AP22,AP29,AP35,AP42,AP47,AP57,AP61,AP62,AP69,AP75,AP80,AP81) -> 94293 | AQ10: =SUM(AQ11,AQ12,AQ13,AQ14,AQ15,AQ19,AQ22,AQ29,AQ35,AQ42,AQ47,AQ57,AQ61,AQ62,AQ69,AQ75,AQ80,AQ81) -> 764 | AR10: =SUM(AR11,AR12,AR13,AR14,AR15,AR19,AR22,AR29,AR35,AR42,AR47,AR57,AR61,AR62,AR69,AR75,AR80,AR81) -> 487 | AS10: =SUM(AS11,AS12,AS13,AS14,AS15,AS19,AS22,AS29,AS35,AS42,AS47,AS57,AS61,AS62,AS69,AS75,AS80,AS81) -> 4
A11: 서울동부지방법원 | B11: =SUM(AI11+D11+C11) -> 365681 | C11: =SUM(E11:G11,N11,R11,T11:V11) -> 44362 | D11: =SUM(H11:M11,O11:Q11,S11,W11:AH11) -> 140401 | E11: 1379 | F11: 7252 | G11: 30024 | H11: 3753 | I11: 40710 | J11: 31319 | K11: 4075 | L11: 21598 | M11: 0 | N11: 0 | O11: 0 | P11: 0 | Q11: 0 | R11: 0 | S11: 1 | T11: 535 | U11: 5171 | V11: 1 | W11: 4927 | X11: 10558 | Y11: 18826 | Z11: 2983 | AA11: 0 | AB11: 361 | AC11: 0 | AD11: 161 | AE11: 0 | AF11: 13 | AG11: 0 | AH11: 1116 | AI11: =SUM(AJ11:AL11) -> 180918 | AJ11: 171664 | AK11: 6072 | AL11: 3182 | AN11: 서울중앙지방법원 | AO11: =SUM(AP11,AQ11,AR11,AS11) -> 7588 | AP11: 7533 | AQ11: 35 | AR11: 20 | AS11: 0
A12: 서울남부지방법원 | B12: =SUM(AI12+D12+C12) -> 557068 | C12: =SUM(E12:G12,N12,R12,T12:V12) -> 67585 | D12: =SUM(H12:M12,O12:Q12,S12,W12:AH12) -> 207282 | E12: 1667 | F12: 11660 | G12: 46311 | H12: 5663 | I12: 75507 | J12: 38990 | K12: 6033 | L12: 29615 | M12: 0 | N12: 0 | O12: 0 | P12: 0 | Q12: 0 | R12: 0 | S12: 0 | T12: 683 | U12: 7257 | V12: 7 | W12: 8193 | X12: 13405 | Y12: 22726 | Z12: 4445 | AA12: 0 | AB12: 673 | AC12: 0 | AD12: 346 | AE12: 0 | AF12: 41 | AG12: 0 | AH12: 1645 | AI12: =SUM(AJ12:AL12) -> 282201 | AJ12: 269085 | AK12: 8141 | AL12: 4975 | AN12: 서울동부지방법원 | AO12: =SUM(AP12,AQ12,AR12,AS12) -> 2983 | AP12: 2976 | AQ12: 5 | AR12: 2 | AS12: 0
A13: 서울북부지방법원 | B13: =SUM(AI13+D13+C13) -> 389155 | C13: =SUM(E13:G13,N13,R13,T13:V13) -> 30453 | D13: =SUM(H13:M13,O13:Q13,S13,W13:AH13) -> 145859 | E13: 766 | F13: 7303 | G13: 14750 | H13: 2532 | I13: 24362 | J13: 43290 | K13: 1678 | L13: 22864 | M13: 0 | N13: 0 | O13: 0 | P13: 0 | Q13: 0 | R13: 0 | S13: 1 | T13: 543 | U13: 7087 | V13: 4 | W13: 10460 | X13: 14059 | Y13: 20608 | Z13: 3329 | AA13: 0 | AB13: 451 | AC13: 0 | AD13: 200 | AE13: 0 | AF13: 58 | AG13: 0 | AH13: 1967 | AI13: =SUM(AJ13:AL13) -> 212843 | AJ13: 197288 | AK13: 9017 | AL13: 6538 | AN13: 서울남부지방법원 | AO13: =SUM(AP13,AQ13,AR13,AS13) -> 4445 | AP13: 4408 | AQ13: 19 | AR13: 18 | AS13: 0
A14: 서울서부지방법원 | B14: =SUM(AI14+D14+C14) -> 342059 | C14: =SUM(E14:G14,N14,R14,T14:V14) -> 30970 | D14: =SUM(H14:M14,O14:Q14,S14,W14:AH14) -> 136422 | E14: 1314 | F14: 9453 | G14: 15359 | H14: 2731 | I14: 53558 | J14: 23813 | K14: 3571 | L14: 18312 | M14: 0 | N14: 0 | O14: 0 | P14: 0 | Q14: 0 | R14: 0 | S14: 1 | T14: 447 | U14: 4396 | V14: 1 | W14: 4130 | X14: 8093 | Y14: 18029 | Z14: 2353 | AA14: 0 | AB14: 384 | AC14: 0 | AD14: 187 | AE14: 0 | AF14: 6 | AG14: 0 | AH14: 1254 | AI14: =SUM(AJ14:AL14) -> 174667 | AJ14: 165642 | AK14: 5480 | AL14: 3545 | AN14: 서울북부지방법원 | AO14: =SUM(AP14,AQ14,AR14,AS14) -> 3329 | AP14: 3297 | AQ14: 26 | AR14: 6 | AS14: 0
A15: 의정부지방법원 | B15: =SUM(AI15+D15+C15) -> 387636 | C15: =SUM(E15:G15,N15,R15,T15:V15) -> 22821 | D15: =SUM(H15:M15,O15:Q15,S15,W15:AH15) -> 133237 | E15: 1083 | F15: 5229 | G15: 5897 | H15: 1669 | I15: 12865 | J15: 34483 | K15: 2310 | L15: 23760 | M15: 12595 | N15: 1509 | O15: 215 | P15: 2869 | Q15: 944 | R15: 1123 | S15: 634 | T15: 632 | U15: 7345 | V15: 3 | W15: 4632 | X15: 10752 | Y15: 13801 | Z15: 3413 | AA15: 4245 | AB15: 677 | AC15: 110 | AD15: 598 | AE15: 47 | AF15: 63 | AG15: 5 | AH15: 2550 | AI15: =SUM(AJ15:AL15) -> 231578 | AJ15: 217551 | AK15: 6442 | AL15: 7585 | AN15: 서울서부지방법원 | AO15: =SUM(AP15,AQ15,AR15,AS15) -> 2353 | AP15: 2330 | AQ15: 16 | AR15: 7 | AS15: 0
A16: 고양지원 | B16: =SUM(AI16+D16+C16) -> 421996 | C16: =SUM(E16:G16,N16,R16,T16:V16) -> 18811 | D16: =SUM(H16:M16,O16:Q16,S16,W16:AH16) -> 110359 | E16: 855 | F16: 4920 | G16: 6786 | H16: 1171 | I16: 14432 | J16: 34592 | K16: 3396 | L16: 22001 | M16: 0 | N16: 1129 | O16: 172 | P16: 2751 | Q16: 865 | R16: 0 | S16: 0 | T16: 412 | U16: 4707 | V16: 2 | W16: 2670 | X16: 9926 | Y16: 13746 | Z16: 2204 | AA16: 0 | AB16: 1015 | AC16: 86 | AD16: 419 | AE16: 16 | AF16: 29 | AG16: 4 | AH16: 864 | AI16: =SUM(AJ16:AL16) -> 292826 | AJ16: 281800 | AK16: 6806 | AL16: 4220 | AN16: 의정부지방법원 | AO16: =SUM(AP16,AQ16,AR16,AS16) -> 3413 | AP16: 3382 | AQ16: 27 | AR16: 4 | AS16: 0
A17: 남양주지원 | B17: =SUM(AI17+D17+C17) -> 256153 | C17: =SUM(E17:G17,N17,R17,T17:V17) -> 6241 | D17: =SUM(H17:M17,O17:Q17,S17,W17:AH17) -> 49515 | E17: 73 | F17: 727 | G17: 4372 | H17: 236 | I17: 9685 | J17: 16274 | K17: 981 | L17: 7471 | M17: 0 | N17: 190 | O17: 88 | P17: 1061 | Q17: 281 | R17: 0 | S17: 1 | T17: 71 | U17: 808 | V17: 0 | W17: 3679 | X17: 2768 | Y17: 5747 | Z17: 343 | AA17: 0 | AB17: 275 | AC17: 19 | AD17: 182 | AE17: 3 | AF17: 0 | AG17: 0 | AH17: 421 | AI17: =SUM(AJ17:AL17) -> 200397 | AJ17: 195986 | AK17: 3546 | AL17: 865 | AN17: 고양지원 | AO17: =SUM(AP17,AQ17,AR17,AS17) -> 2204 | AP17: 2194 | AQ17: 9 | AR17: 1 | AS17: 0
A18: 소 계 | B18: =SUM(AI18+D18+C18) -> 1065785 | C18: =SUM(C15:C17) -> 47873 | D18: =SUM(H18:M18,O18:Q18,S18,W18:AH18) -> 293111 | E18: 2011 | F18: 10876 | G18: 17055 | H18: 3076 | I18: 36982 | J18: 85349 | K18: 6687 | L18: 53232 | M18: 12595 | N18: 2828 | O18: 475 | P18: 6681 | Q18: 2090 | R18: 1123 | S18: 635 | T18: 1115 | U18: 12860 | V18: 5 | W18: 10981 | X18: 23446 | Y18: 33294 | Z18: 5960 | AA18: 4245 | AB18: 1967 | AC18: 215 | AD18: 1199 | AE18: 66 | AF18: 92 | AG18: 9 | AH18: 3835 | AI18: =SUM(AJ18:AL18) -> 724801 | AJ18: 695337 | AK18: 16794 | AL18: 12670 | AN18: 남양주지원 | AO18: =SUM(AP18,AQ18,AR18,AS18) -> 343 | AP18: 334 | AQ18: 5 | AR18: 4 | AS18: 0
A19: 인천지방법원 | B19: =SUM(AI19+D19+C19) -> 878285 | C19: =SUM(E19:G19,N19,R19,T19:V19) -> 49260 | D19: =SUM(H19:M19,O19:Q19,S19,W19:AH19) -> 290671 | E19: 1585 | F19: 10717 | G19: 20379 | H19: 5166 | I19: 38935 | J19: 81376 | K19: 5582 | L19: 46189 | M19: 20016 | N19: 0 | O19: 0 | P19: 0 | Q19: 0 | R19: 1866 | S19: 592 | T19: 1412 | U19: 13292 | V19: 9 | W19: 14858 | X19: 26112 | Y19: 40690 | Z19: 6945 | AA19: 0 | AB19: 0 | AC19: 0 | AD19: 0 | AE19: 0 | AF19: 121 | AG19: 0 | AH19: 4089 | AI19: =SUM(AJ19:AL19) -> 538354 | AJ19: 527035 | AK19: 0 | AL19: 11319 | AN19: 소계 | AO19: =SUM(AP19,AQ19,AR19,AS19) -> 5960 | AP19: 5910 | AQ19: 41 | AR19: 9 | AS19: 0
A20: 인천가정법원 | B20: =SUM(AI20+D20+C20) -> 36246 | C20: =SUM(E20:G20,N20,R20,T20:V20) -> 2649 | D20: =SUM(H20:M20,O20:Q20,S20,W20:AH20) -> 18010 | G20: 0 | H20: 0 | I20: 0 | J20: 0 | K20: 0 | L20: 0 | M20: 0 | N20: 2649 | O20: 957 | P20: 5586 | Q20: 1566 | R20: 0 | S20: 0 | T20: 0 | U20: 0 | V20: 0 | W20: 0 | X20: 0 | Y20: 0 | Z20: 0 | AA20: 4350 | AB20: 3696 | AC20: 171 | AD20: 1489 | AE20: 119 | AF20: 0 | AG20: 5 | AH20: 71 | AI20: =SUM(AJ20:AL20) -> 15587 | AJ20: 0 | AK20: 15587 | AL20: 0 | AN20: 인천지방법원 | AO20: =SUM(AP20,AQ20,AR20,AS20) -> 6945 | AP20: 6868 | AQ20: 40 | AR20: 37 | AS20: 0
A21: 부천지원 | B21: =SUM(AI21+D21+C21) -> 369110 | C21: =SUM(E21:G21,N21,R21,T21:V21) -> 19666 | D21: =SUM(H21:M21,O21:Q21,S21,W21:AH21) -> 97545 | E21: 492 | F21: 4422 | G21: 7534 | H21: 312 | I21: 12552 | J21: 29339 | K21: 1984 | L21: 17087 | M21: 0 | N21: 1053 | O21: 166 | P21: 2223 | Q21: 733 | R21: 0 | S21: 0 | T21: 380 | U21: 5782 | V21: 3 | W21: 3967 | X21: 10876 | Y21: 12516 | Z21: 2049 | AA21: 0 | AB21: 1430 | AC21: 124 | AD21: 871 | AE21: 43 | AF21: 28 | AG21: 4 | AH21: 1241 | AI21: =SUM(AJ21:AL21) -> 251899 | AJ21: 242988 | AK21: 6246 | AL21: 2665 | AN21: 부천지원 | AO21: =SUM(AP21,AQ21,AR21,AS21) -> 2049 | AP21: 2029 | AQ21: 15 | AR21: 4 | AS21: 1
A22: 소 계 | B22: =SUM(AI22+D22+C22) -> 1283641 | C22: =SUM(C19:C21) -> 71575 | D22: =SUM(H22:M22,O22:Q22,S22,W22:AH22) -> 406226 | E22: 2077 | F22: 15139 | G22: 27913 | H22: 5478 | I22: 51487 | J22: 110715 | K22: 7566 | L22: 63276 | M22: 20016 | N22: 3702 | O22: 1123 | P22: 7809 | Q22: 2299 | R22: 1866 | S22: 592 | T22: 1792 | U22: 19074 | V22: 12 | W22: 18825 | X22: 36988 | Y22: 53206 | Z22: 8994 | AA22: 4350 | AB22: 5126 | AC22: 295 | AD22: 2360 | AE22: 162 | AF22: 149 | AG22: 9 | AH22: 5401 | AI22: =SUM(AJ22:AL22) -> 805840 | AJ22: 770023 | AK22: 21833 | AL22: 13984 | AN22: 소계 | AO22: =SUM(AP22,AQ22,AR22,AS22) -> 8994 | AP22: 8897 | AQ22: 55 | AR22: 41 | AS22: 1
A23: 수원지방법원 | B23: =SUM(AI23+D23+C23) -> 1121004 | C23: =SUM(E23:G23,N23,R23,T23:V23) -> 44681 | D23: =SUM(H23:M23,O23:Q23,S23,W23:AH23) -> 254895 | E23: 2075 | F23: 9435 | G23: 18546 | H23: 5111 | I23: 35543 | J23: 64719 | K23: 6457 | L23: 41557 | M23: 27677 | N23: 0 | O23: 0 | P23: 0 | Q23: 0 | R23: 3229 | S23: 1305 | T23: 1113 | U23: 10275 | V23: 8 | W23: 5705 | X23: 24553 | Y23: 33203 | Z23: 5498 | AA23: 0 | AB23: 0 | AC23: 0 | AD23: 0 | AE23: 0 | AF23: 117 | AG23: 0 | AH23: 3450 | AI23: =SUM(AJ23:AL23) -> 821428 | AJ23: 810278 | AK23: 0 | AL23: 11150 | AN23: 수원지방법원 | AO23: =SUM(AP23,AQ23,AR23,AS23) -> 5498 | AP23: 5460 | AQ23: 23 | AR23: 14 | AS23: 1
A24: 수원가정법원 | B24: =SUM(AI24+D24+C24) -> 39209 | C24: =SUM(E24:G24,N24,R24,T24:V24) -> 2582 | D24: =SUM(H24:M24,O24:Q24,S24,W24:AH24) -> 22550 | G24: 0 | H24: 0 | I24: 0 | J24: 0 | K24: 0 | L24: 0 | M24: 0 | N24: 2582 | O24: 501 | P24: 4569 | Q24: 1785 | R24: 0 | S24: 0 | T24: 0 | U24: 0 | V24: 0 | W24: 0 | X24: 0 | Y24: 0 | Z24: 0 | AA24: 10368 | AB24: 3518 | AC24: 203 | AD24: 1455 | AE24: 64 | AF24: 0 | AG24: 16 | AH24: 71 | AI24: =SUM(AJ24:AL24) -> 14077 | AJ24: 0 | AK24: 14077 | AL24: 0 | AN24: 성남지원 | AO24: =SUM(AP24,AQ24,AR24,AS24) -> 1540 | AP24: 1532 | AQ24: 8 | AR24: 0 | AS24: 0
A25: 성남지원 | B25: =SUM(AI25+D25+C25) -> 435470 | C25: =SUM(E25:G25,N25,R25,T25:V25) -> 23480 | D25: =SUM(H25:M25,O25:Q25,S25,W25:AH25) -> 109616 | E25: 1237 | F25: 6197 | G25: 9683 | H25: 939 | I25: 16124 | J25: 31540 | K25: 4063 | L25: 19958 | M25: 0 | N25: 1275 | O25: 268 | P25: 2420 | Q25: 819 | R25: 0 | S25: 0 | T25: 466 | U25: 4621 | V25: 1 | W25: 4084 | X25: 11299 | Y25: 13063 | Z25: 1540 | AA25: 0 | AB25: 1523 | AC25: 64 | AD25: 577 | AE25: 28 | AF25: 8 | AG25: 3 | AH25: 1296 | AI25: =SUM(AJ25:AL25) -> 302374 | AJ25: 291281 | AK25: 6845 | AL25: 4248 | AN25: 여주지원 | AO25: =SUM(AP25,AQ25,AR25,AS25) -> 644 | AP25: 637 | AQ25: 7 | AR25: 0 | AS25: 0
A26: 여주지원 | B26: =SUM(AI26+D26+C26) -> 91869 | C26: =SUM(E26:G26,N26,R26,T26:V26) -> 6676 | D26: =SUM(H26:M26,O26:Q26,S26,W26:AH26) -> 36598 | E26: 268 | F26: 1886 | G26: 2375 | H26: 97 | I26: 4543 | J26: 11951 | K26: 728 | L26: 7262 | M26: 0 | N26: 346 | O26: 56 | P26: 928 | Q26: 236 | R26: 0 | S26: 0 | T26: 174 | U26: 1625 | V26: 2 | W26: 726 | X26: 4559 | Y26: 3814 | Z26: 644 | AA26: 0 | AB26: 458 | AC26: 32 | AD26: 156 | AE26: 15 | AF26: 2 | AG26: 2 | AH26: 389 | AI26: =SUM(AJ26:AL26) -> 48595 | AJ26: 44462 | AK26: 2358 | AL26: 1775 | AN26: 평택지원 | AO26: =SUM(AP26,AQ26,AR26,AS26) -> 1523 | AP26: 1508 | AQ26: 10 | AR26: 5 | AS26: 0
A27: 평택지원 | B27: =SUM(AI27+D27+C27) -> 179836 | C27: =SUM(E27:G27,N27,R27,T27:V27) -> 12820 | D27: =SUM(H27:M27,O27:Q27,S27,W27:AH27) -> 73870 | E27: 448 | F27: 2806 | G27: 4284 | H27: 119 | I27: 9149 | J27: 23807 | K27: 828 | L27: 13549 | M27: 0 | N27: 694 | O27: 101 | P27: 1301 | Q27: 447 | R27: 0 | S27: 0 | T27: 285 | U27: 4302 | V27: 1 | W27: 1790 | X27: 10047 | Y27: 8449 | Z27: 1523 | AA27: 0 | AB27: 1006 | AC27: 41 | AD27: 316 | AE27: 9 | AF27: 9 | AG27: 6 | AH27: 1373 | AI27: =SUM(AJ27:AL27) -> 93146 | AJ27: 85966 | AK27: 4256 | AL27: 2924 | AN27: 안산지원 | AO27: =SUM(AP27,AQ27,AR27,AS27) -> 2537 | AP27: 2500 | AQ27: 31 | AR27: 6 | AS27: 0
A28: 안산지원 | B28: =SUM(AI28+D28+C28) -> 402012 | C28: =SUM(E28:G28,N28,R28,T28:V28) -> 23039 | D28: =SUM(H28:M28,O28:Q28,S28,W28:AH28) -> 126591 | E28: 691 | F28: 4727 | G28: 8698 | H28: 490 | I28: 15975 | J28: 38421 | K28: 2613 | L28: 21821 | M28: 0 | N28: 1298 | O28: 181 | P28: 2339 | Q28: 730 | R28: 0 | S28: 0 | T28: 711 | U28: 6912 | V28: 2 | W28: 6027 | X28: 15633 | Y28: 13887 | Z28: 2537 | AA28: 0 | AB28: 2915 | AC28: 188 | AD28: 1004 | AE28: 104 | AF28: 29 | AG28: 5 | AH28: 1692 | AI28: =SUM(AJ28:AL28) -> 252382 | AJ28: 240192 | AK28: 7448 | AL28: 4742 | AN28: 안양지원 | AO28: =SUM(AP28,AQ28,AR28,AS28) -> 1154 | AP28: 1142 | AQ28: 8 | AR28: 4 | AS28: 0
A29: 안양지원 | B29: =SUM(AI29+D29+C29) -> 225849 | C29: =SUM(E29:G29,N29,R29,T29:V29) -> 12997 | D29: =SUM(H29:M29,O29:Q29,S29,W29:AH29) -> 58148 | E29: 636 | F29: 3164 | G29: 5369 | H29: 172 | I29: 8785 | J29: 16798 | K29: 856 | L29: 10791 | M29: 0 | N29: 741 | O29: 122 | P29: 1461 | Q29: 410 | R29: 0 | S29: 1 | T29: 314 | U29: 2773 | V29: 0 | W29: 1877 | X29: 5516 | Y29: 7795 | Z29: 1154 | AA29: 0 | AB29: 1049 | AC29: 25 | AD29: 352 | AE29: 16 | AF29: 31 | AG29: 4 | AH29: 933 | AI29: =SUM(AJ29:AL29) -> 154704 | AJ29: 149091 | AK29: 3804 | AL29: 1809 | AN29: 소계 | AO29: =SUM(AP29,AQ29,AR29,AS29) -> 12896 | AP29: 12779 | AQ29: 87 | AR29: 29 | AS29: 1
A30: 소 계 | B30: =SUM(AI30+D30+C30) -> 2495249 | C30: =SUM(C23:C29) -> 126275 | D30: =SUM(H30:M30,O30:Q30,S30,W30:AH30) -> 682268 | E30: 5355 | F30: 28215 | G30: 48955 | H30: 6928 | I30: 90119 | J30: 187236 | K30: 15545 | L30: 114938 | M30: 27677 | N30: 6936 | O30: 1229 | P30: 13018 | Q30: 4427 | R30: 3229 | S30: 1306 | T30: 3063 | U30: 30508 | V30: 14 | W30: 20209 | X30: 71607 | Y30: 80211 | Z30: 12896 | AA30: 10368 | AB30: 10469 | AC30: 553 | AD30: 3860 | AE30: 236 | AF30: 196 | AG30: 36 | AH30: 9204 | AI30: =SUM(AJ30:AL30) -> 1686706 | AJ30: 1621270 | AK30: 38788 | AL30: 26648 | AN30: 춘천지방법원 | AO30: =SUM(AP30,AQ30,AR30,AS30) -> 985 | AP30: 966 | AQ30: 10 | AR30: 9 | AS30: 0
A31: 춘천지방법원 | B31: =SUM(AI31+D31+C31) -> 275668 | C31: =SUM(E31:G31,N31,R31,T31:V31) -> 5870 | D31: =SUM(H31:M31,O31:Q31,S31,W31:AH31) -> 37030 | E31: 177 | F31: 1154 | G31: 1549 | H31: 929 | I31: 4592 | J31: 9175 | K31: 257 | L31: 5107 | M31: 3135 | N31: 319 | O31: 55 | P31: 814 | Q31: 167 | R31: 353 | S31: 218 | T31: 193 | U31: 2125 | V31: 0 | W31: 635 | X31: 3551 | Y31: 4839 | Z31: 985 | AA31: 1725 | AB31: 283 | AC31: 24 | AD31: 91 | AE31: 7 | AF31: 1 | AG31: 0 | AH31: 440 | AI31: =SUM(AJ31:AL31) -> 232768 | AJ31: 229039 | AK31: 1979 | AL31: 1750 | AN31: 강릉지원 | AO31: =SUM(AP31,AQ31,AR31,AS31) -> 485 | AP31: 477 | AQ31: 7 | AR31: 1 | AS31: 0
A32: 강릉지원 | B32: =SUM(AI32+D32+C32) -> 78672 | C32: =SUM(E32:G32,N32,R32,T32:V32) -> 4463 | D32: =SUM(H32:M32,O32:Q32,S32,W32:AH32) -> 28215 | E32: 173 | F32: 1023 | G32: 1316 | H32: 261 | I32: 3864 | J32: 8741 | K32: 392 | L32: 5010 | M32: 1100 | N32: 268 | O32: 20 | P32: 761 | Q32: 219 | R32: 99 | S32: 65 | T32: 109 | U32: 1474 | V32: 1 | W32: 433 | X32: 2999 | Y32: 2962 | Z32: 485 | AA32: 0 | AB32: 344 | AC32: 7 | AD32: 103 | AE32: 14 | AF32: 1 | AG32: 0 | AH32: 434 | AI32: =SUM(AJ32:AL32) -> 45994 | AJ32: 42895 | AK32: 1877 | AL32: 1222 | AN32: 원주지원 | AO32: =SUM(AP32,AQ32,AR32,AS32) -> 810 | AP32: 784 | AQ32: 20 | AR32: 6 | AS32: 0
A33: 원주지원 | B33: =SUM(AI33+D33+C33) -> 116776 | C33: =SUM(E33:G33,N33,R33,T33:V33) -> 6807 | D33: =SUM(H33:M33,O33:Q33,S33,W33:AH33) -> 32108 | E33: 322 | F33: 1516 | G33: 2153 | H33: 75 | I33: 4958 | J33: 11103 | K33: 299 | L33: 5900 | M33: 0 | N33: 316 | O33: 23 | P33: 792 | Q33: 231 | R33: 0 | S33: 0 | T33: 171 | U33: 2329 | V33: 0 | W33: 497 | X33: 2773 | Y33: 3547 | Z33: 810 | AA33: 0 | AB33: 425 | AC33: 39 | AD33: 173 | AE33: 11 | AF33: 2 | AG33: 1 | AH33: 449 | AI33: =SUM(AJ33:AL33) -> 77861 | AJ33: 74260 | AK33: 2357 | AL33: 1244 | AN33: 속초지원 | AO33: =SUM(AP33,AQ33,AR33,AS33) -> 240 | AP33: 237 | AQ33: 1 | AR33: 2 | AS33: 0
A34: 속초지원 | B34: =SUM(AI34+D34+C34) -> 35641 | C34: =SUM(E34:G34,N34,R34,T34:V34) -> 2133 | D34: =SUM(H34:M34,O34:Q34,S34,W34:AH34) -> 11909 | E34: 89 | F34: 477 | G34: 559 | H34: 21 | I34: 1499 | J34: 3900 | K34: 127 | L34: 2209 | M34: 0 | N34: 106 | O34: 15 | P34: 278 | Q34: 69 | R34: 0 | S34: 0 | T34: 85 | U34: 815 | V34: 2 | W34: 221 | X34: 1539 | Y34: 1463 | Z34: 240 | AA34: 0 | AB34: 128 | AC34: 3 | AD34: 26 | AE34: 1 | AF34: 0 | AG34: 0 | AH34: 170 | AI34: =SUM(AJ34:AL34) -> 21599 | AJ34: 20456 | AK34: 697 | AL34: 446 | AN34: 영월지원 | AO34: =SUM(AP34,AQ34,AR34,AS34) -> 207 | AP34: 200 | AQ34: 5 | AR34: 2 | AS34: 0
